<?xml version="1.0" ?>
<!-- Generated using onshape-to-robot -->
<!-- Onshape https://cad.onshape.com/documents/0f7ba08d49760d832652e76c/w/f802382a554ac4e5d967eb06/e/176c79e9883e5c00c7190ba1 -->
<robot name="momo_urdf">
    <!-- Link base_link -->
    <link name="base_link">
        <inertial>
            <origin xyz="-0.0143671 0.000390804 0.148205" rpy="0 0 0"/>
            <mass value="21.7918"/>
            <inertia ixx="1.00393" ixy="-0.00124035" ixz="0.0559784" iyy="1.72995" iyz="-0.00112567" izz="1.89383"/>
        </inertial>
        <!-- Part base_link_parts -->
        <collision>
            <origin xyz="-2.81025e-16 3.73291e-16 0.1125" rpy="-3.71182e-14 -4.46553e-15 3.39654e-15"/>
            <geometry>
                <box size="0.745 0.44 0.225"/>
            </geometry>
        </collision>
        <collision>
            <origin xyz="-0.0546499 -1.4351e-13 0.363815" rpy="-3.83322e-15 1.39378e-14 1.5708"/>
            <geometry>
                <box size="0.435 0.645 0.276"/>
            </geometry>
        </collision>
        <visual>
            <origin xyz="-0.0143671 0.000390804 0.148205" rpy="0 -0 0"/>
            <geometry>
                <mesh filename="package://assets/merged/base_link_visual.stl"/>
            </geometry>
            <material name="base_link_parts_material">
                <color rgba="0.811313 0.816187 0.835458 1.0"/>
            </material>
        </visual>
    </link>
    <!-- Frame velodyne_frame (dummy link + fixed joint) -->
    <link name="velodyne_frame">
        <origin xyz="0 0 0" rpy="0 -0 0"/>
        <inertial>
            <origin xyz="0 0 0" rpy="0 0 0"/>
            <mass value="1e-9"/>
            <inertia ixx="0" ixy="0" ixz="0" iyy="0" iyz="0" izz="0"/>
        </inertial>
    </link>
    <joint name="velodyne_frame_frame" type="fixed">
        <origin xyz="-0.00693293 1.75362e-07 0.467529" rpy="1.66614e-14 4.87655e-14 -1.5708"/>
        <parent link="base_link"/>
        <child link="velodyne_frame"/>
        <axis xyz="0 0 0"/>
    </joint>
    <!-- Frame front_logitech_frame (dummy link + fixed joint) -->
    <link name="front_logitech_frame">
        <origin xyz="0 0 0" rpy="0 -0 0"/>
        <inertial>
            <origin xyz="0 0 0" rpy="0 0 0"/>
            <mass value="1e-9"/>
            <inertia ixx="0" ixy="0" ixz="0" iyy="0" iyz="0" izz="0"/>
        </inertial>
    </link>
    <joint name="front_logitech_frame_frame" type="fixed">
        <origin xyz="0.150217 -1.41843e-05 0.408222" rpy="-1.5708 -3.69437e-14 -1.5708"/>
        <parent link="base_link"/>
        <child link="front_logitech_frame"/>
        <axis xyz="0 0 0"/>
    </joint>
    <!-- Frame left_logitech_frame (dummy link + fixed joint) -->
    <link name="left_logitech_frame">
        <origin xyz="0 0 0" rpy="0 -0 0"/>
        <inertial>
            <origin xyz="0 0 0" rpy="0 0 0"/>
            <mass value="1e-9"/>
            <inertia ixx="0" ixy="0" ixz="0" iyy="0" iyz="0" izz="0"/>
        </inertial>
    </link>
    <joint name="left_logitech_frame_frame" type="fixed">
        <origin xyz="-0.00691857 0.20665 0.408222" rpy="-1.5708 -3.31108e-15 -9.16481e-14"/>
        <parent link="base_link"/>
        <child link="left_logitech_frame"/>
        <axis xyz="0 0 0"/>
    </joint>
    <!-- Frame right_logitech_frame (dummy link + fixed joint) -->
    <link name="right_logitech_frame">
        <origin xyz="0 0 0" rpy="0 -0 0"/>
        <inertial>
            <origin xyz="0 0 0" rpy="0 0 0"/>
            <mass value="1e-9"/>
            <inertia ixx="0" ixy="0" ixz="0" iyy="0" iyz="0" izz="0"/>
        </inertial>
    </link>
    <joint name="right_logitech_frame_frame" type="fixed">
        <origin xyz="-0.00694694 -0.20665 0.408222" rpy="-1.5708 1.96259e-15 3.14159"/>
        <parent link="base_link"/>
        <child link="right_logitech_frame"/>
        <axis xyz="0 0 0"/>
    </joint>
    <!-- Frame back_logitech_frame (dummy link + fixed joint) -->
    <link name="back_logitech_frame">
        <origin xyz="0 0 0" rpy="0 -0 0"/>
        <inertial>
            <origin xyz="0 0 0" rpy="0 0 0"/>
            <mass value="1e-9"/>
            <inertia ixx="0" ixy="0" ixz="0" iyy="0" iyz="0" izz="0"/>
        </inertial>
    </link>
    <joint name="back_logitech_frame_frame" type="fixed">
        <origin xyz="-0.259083 1.41843e-05 0.408222" rpy="-1.5708 8.29069e-14 1.5708"/>
        <parent link="base_link"/>
        <child link="back_logitech_frame"/>
        <axis xyz="0 0 0"/>
    </joint>
    <!-- Frame front_realsense_frame (dummy link + fixed joint) -->
    <link name="front_realsense_frame">
        <origin xyz="0 0 0" rpy="0 -0 0"/>
        <inertial>
            <origin xyz="0 0 0" rpy="0 0 0"/>
            <mass value="1e-9"/>
            <inertia ixx="0" ixy="0" ixz="0" iyy="0" iyz="0" izz="0"/>
        </inertial>
    </link>
    <joint name="front_realsense_frame_frame" type="fixed">
        <origin xyz="0.272296 -0.00478981 0.31864" rpy="-1.5708 -3.69437e-14 -1.5708"/>
        <parent link="base_link"/>
        <child link="front_realsense_frame"/>
        <axis xyz="0 0 0"/>
    </joint>
    <!-- Frame back_realsense_frame (dummy link + fixed joint) -->
    <link name="back_realsense_frame">
        <origin xyz="0 0 0" rpy="0 -0 0"/>
        <inertial>
            <origin xyz="0 0 0" rpy="0 0 0"/>
            <mass value="1e-9"/>
            <inertia ixx="0" ixy="0" ixz="0" iyy="0" iyz="0" izz="0"/>
        </inertial>
    </link>
    <joint name="back_realsense_frame_frame" type="fixed">
        <origin xyz="-0.381177 0.000689294 0.31717" rpy="-1.5708 3.69437e-14 1.5708"/>
        <parent link="base_link"/>
        <child link="back_realsense_frame"/>
        <axis xyz="0 0 0"/>
    </joint>
    <!-- Link front_right_wheel -->
    <link name="front_right_wheel">
        <inertial>
            <origin xyz="3.47093e-06 -2.04554e-05 -0.039002" rpy="0 0 0"/>
            <mass value="0.942157"/>
            <inertia ixx="0.00202095" ixy="-9.2256e-07" ixz="-8.13728e-12" iyy="0.00202623" iyz="2.75701e-11" izz="0.00255146"/>
        </inertial>
        <!-- Part front_right_wheel_parts -->
        <visual>
            <origin xyz="3.47093e-06 -2.04554e-05 -0.039002" rpy="1.5708 3.44801e-15 -3.14159"/>
            <geometry>
                <mesh filename="package://assets/merged/front_right_wheel_visual.stl"/>
            </geometry>
            <material name="front_right_wheel_parts_material">
                <color rgba="0.792157 0.819608 0.933333 1.0"/>
            </material>
        </visual>
    </link>
    <!-- Link roller -->
    <link name="roller">
        <inertial>
            <origin xyz="1.53093e-16 -1.17991e-16 -3.69571e-16" rpy="0 0 0"/>
            <mass value="0.0493467"/>
            <inertia ixx="1.86522e-05" ixy="-1.99218e-21" ixz="2.15734e-21" iyy="1.86522e-05" iyz="9.35556e-22" izz="5.80503e-06"/>
        </inertial>
        <!-- Part roller_parts -->
        <collision>
            <origin xyz="-2.06877e-17 2.16553e-17 -1.36281e-16" rpy="-1.55462e-16 -8.97457e-17 1.82843e-18"/>
            <geometry>
                <sphere radius="0.0155"/>
            </geometry>
        </collision>
        <collision>
            <origin xyz="-2.61999e-17 1.31575e-18 0.0085" rpy="-1.55462e-16 -8.97457e-17 1.82843e-18"/>
            <geometry>
                <sphere radius="0.0155"/>
            </geometry>
        </collision>
        <collision>
            <origin xyz="-1.51842e-17 4.22501e-17 -0.0085" rpy="-1.55462e-16 -8.97457e-17 1.82843e-18"/>
            <geometry>
                <sphere radius="0.0155"/>
            </geometry>
        </collision>
        <collision>
            <origin xyz="-3.01225e-17 2.18785e-17 0.0165" rpy="-1.55462e-16 -8.97457e-17 1.82843e-18"/>
            <geometry>
                <sphere radius="0.015"/>
            </geometry>
        </collision>
        <collision>
            <origin xyz="-1.10447e-17 2.16873e-17 -0.0165" rpy="-1.55462e-16 -8.97457e-17 1.82843e-18"/>
            <geometry>
                <sphere radius="0.015"/>
            </geometry>
        </collision>
        <collision>
            <origin xyz="-1.63128e-17 3.99712e-17 0.0235" rpy="-1.55462e-16 -8.97457e-17 1.82843e-18"/>
            <geometry>
                <sphere radius="0.014"/>
            </geometry>
        </collision>
        <collision>
            <origin xyz="-2.48544e-17 3.59466e-18 -0.0235" rpy="-1.55462e-16 -8.97457e-17 1.82843e-18"/>
            <geometry>
                <sphere radius="0.014"/>
            </geometry>
        </collision>
        <visual>
            <origin xyz="1.38778e-16 -1.45717e-16 -3.88578e-16" rpy="-1.73657 -0.771399 1.42161"/>
            <geometry>
                <mesh filename="package://assets/merged/roller_visual.stl"/>
            </geometry>
            <material name="roller_parts_material">
                <color rgba="0.752941 0.752941 0.752941 1.0"/>
            </material>
        </visual>
    </link>
    <!-- Joint from front_right_wheel to roller -->
    <joint name="frw_r1" type="revolute">
        <origin xyz="-0.0143011 0.0872364 -0.0394963" rpy="2.39411 -0.268603 -1.68155"/>
        <parent link="front_right_wheel"/>
        <child link="roller"/>
        <axis xyz="0 0 1"/>
        <limit effort="10" velocity="10" lower="-3.141592653589793" upper="3.141592653589793"/>
    </joint>
    <!-- Link roller_2 -->
    <link name="roller_2">
        <inertial>
            <origin xyz="1.23459e-16 -1.34345e-16 -4.04729e-16" rpy="0 0 0"/>
            <mass value="0.0493467"/>
            <inertia ixx="1.86522e-05" ixy="-2.66229e-21" ixz="1.04939e-21" iyy="1.86522e-05" iyz="-1.14284e-21" izz="5.80503e-06"/>
        </inertial>
        <!-- Part roller_2_parts -->
        <collision>
            <origin xyz="-5.03213e-17 5.30139e-18 -1.71439e-16" rpy="-9.36852e-17 -6.78589e-17 -3.70084e-17"/>
            <geometry>
                <sphere radius="0.0155"/>
            </geometry>
        </collision>
        <collision>
            <origin xyz="-5.50182e-17 1.3195e-17 0.0085" rpy="-9.36852e-17 -6.78589e-17 -3.70084e-17"/>
            <geometry>
                <sphere radius="0.0155"/>
            </geometry>
        </collision>
        <collision>
            <origin xyz="-4.56138e-17 -2.35864e-18 -0.0085" rpy="-9.36852e-17 -6.78589e-17 -3.70084e-17"/>
            <geometry>
                <sphere radius="0.0155"/>
            </geometry>
        </collision>
        <collision>
            <origin xyz="-6.50848e-17 2.09024e-17 0.0165" rpy="-9.36852e-17 -6.78589e-17 -3.70084e-17"/>
            <geometry>
                <sphere radius="0.015"/>
            </geometry>
        </collision>
        <collision>
            <origin xyz="-3.59809e-17 -1.06081e-17 -0.0165" rpy="-9.36852e-17 -6.78589e-17 -3.70084e-17"/>
            <geometry>
                <sphere radius="0.015"/>
            </geometry>
        </collision>
        <collision>
            <origin xyz="-6.18019e-17 3.33527e-17 0.0235" rpy="-9.36852e-17 -6.78589e-17 -3.70084e-17"/>
            <geometry>
                <sphere radius="0.014"/>
            </geometry>
        </collision>
        <collision>
            <origin xyz="-3.92637e-17 -2.295e-17 -0.0235" rpy="-9.36852e-17 -6.78589e-17 -3.70084e-17"/>
            <geometry>
                <sphere radius="0.014"/>
            </geometry>
        </collision>
        <visual>
            <origin xyz="1.11022e-16 -1.249e-16 -3.88578e-16" rpy="-2.13858 -0.575895 2.05017"/>
            <geometry>
                <mesh filename="package://assets/merged/roller_2_visual.stl"/>
            </geometry>
            <material name="roller_2_parts_material">
                <color rgba="0.752941 0.752941 0.752941 1.0"/>
            </material>
        </visual>
    </link>
    <!-- Joint from front_right_wheel to roller_2 -->
    <joint name="frw_r2" type="revolute">
        <origin xyz="-0.0560033 0.0683983 -0.0394963" rpy="2.39411 -0.268603 -1.15795"/>
        <parent link="front_right_wheel"/>
        <child link="roller_2"/>
        <axis xyz="0 0 1"/>
        <limit effort="10" velocity="10" lower="-3.141592653589793" upper="3.141592653589793"/>
    </joint>
    <!-- Link roller_3 -->
    <link name="roller_3">
        <inertial>
            <origin xyz="-1.22608e-17 -1.79332e-16 -4.33676e-16" rpy="0 0 0"/>
            <mass value="0.0493467"/>
            <inertia ixx="1.86522e-05" ixy="-4.01024e-21" ixz="3.09904e-21" iyy="1.86522e-05" iyz="-2.02581e-21" izz="5.80503e-06"/>
        </inertial>
        <!-- Part roller_3_parts -->
        <collision>
            <origin xyz="-1.86041e-16 -3.96854e-17 -2.00386e-16" rpy="-2.07104e-16 -9.52601e-17 3.9323e-18"/>
            <geometry>
                <sphere radius="0.0155"/>
            </geometry>
        </collision>
        <collision>
            <origin xyz="-1.81684e-16 -4.85276e-17 0.0085" rpy="-2.07104e-16 -9.52601e-17 3.9323e-18"/>
            <geometry>
                <sphere radius="0.0155"/>
            </geometry>
        </collision>
        <collision>
            <origin xyz="-1.90359e-16 -3.09775e-17 -0.0085" rpy="-2.07104e-16 -9.52601e-17 3.9323e-18"/>
            <geometry>
                <sphere radius="0.0155"/>
            </geometry>
        </collision>
        <collision>
            <origin xyz="-1.74532e-16 -5.33717e-17 0.0165" rpy="-2.07104e-16 -9.52601e-17 3.9323e-18"/>
            <geometry>
                <sphere radius="0.015"/>
            </geometry>
        </collision>
        <collision>
            <origin xyz="-1.97944e-16 -2.61334e-17 -0.0165" rpy="-2.07104e-16 -9.52601e-17 3.9323e-18"/>
            <geometry>
                <sphere radius="0.015"/>
            </geometry>
        </collision>
        <collision>
            <origin xyz="-1.75446e-16 -6.46498e-17 0.0235" rpy="-2.07104e-16 -9.52601e-17 3.9323e-18"/>
            <geometry>
                <sphere radius="0.014"/>
            </geometry>
        </collision>
        <collision>
            <origin xyz="-1.9703e-16 -1.48553e-17 -0.0235" rpy="-2.07104e-16 -9.52601e-17 3.9323e-18"/>
            <geometry>
                <sphere radius="0.014"/>
            </geometry>
        </collision>
        <visual>
            <origin xyz="-5.55112e-17 -1.56125e-16 -4.16334e-16" rpy="-2.32393 -0.248666 2.50013"/>
            <geometry>
                <mesh filename="package://assets/merged/roller_3_visual.stl"/>
            </geometry>
            <material name="roller_3_parts_material">
                <color rgba="0.752941 0.752941 0.752941 1.0"/>
            </material>
        </visual>
    </link>
    <!-- Joint from front_right_wheel to roller_3 -->
    <joint name="frw_r3" type="revolute">
        <origin xyz="-0.0806228 0.0299326 -0.039" rpy="2.39411 -0.268603 -0.634348"/>
        <parent link="front_right_wheel"/>
        <child link="roller_3"/>
        <axis xyz="0 0 1"/>
        <limit effort="10" velocity="10" lower="-3.141592653589793" upper="3.141592653589793"/>
    </joint>
    <!-- Link roller_4 -->
    <link name="roller_4">
        <inertial>
            <origin xyz="1.28391e-16 -1.67554e-16 -4.01328e-16" rpy="0 0 0"/>
            <mass value="0.0493467"/>
            <inertia ixx="1.86522e-05" ixy="1.0404e-21" ixz="8.65364e-22" iyy="1.86522e-05" iyz="-3.70921e-21" izz="5.80503e-06"/>
        </inertial>
        <!-- Part roller_4_parts -->
        <collision>
            <origin xyz="-4.5389e-17 -2.79075e-17 -1.68038e-16" rpy="-2.44036e-16 -1.95133e-16 9.01467e-18"/>
            <geometry>
                <sphere radius="0.0155"/>
            </geometry>
        </collision>
        <collision>
            <origin xyz="-4.34953e-17 -5.54882e-17 0.0085" rpy="-2.44036e-16 -1.95133e-16 9.01467e-18"/>
            <geometry>
                <sphere radius="0.0155"/>
            </geometry>
        </collision>
        <collision>
            <origin xyz="-4.7253e-17 -4.0881e-19 -0.0085" rpy="-2.44036e-16 -1.95133e-16 9.01467e-18"/>
            <geometry>
                <sphere radius="0.0155"/>
            </geometry>
        </collision>
        <collision>
            <origin xyz="-3.45887e-17 -3.6549e-17 0.0165" rpy="-2.44036e-16 -1.95133e-16 9.01467e-18"/>
            <geometry>
                <sphere radius="0.015"/>
            </geometry>
        </collision>
        <collision>
            <origin xyz="-5.61596e-17 -1.90228e-17 -0.0165" rpy="-2.44036e-16 -1.95133e-16 9.01467e-18"/>
            <geometry>
                <sphere radius="0.015"/>
            </geometry>
        </collision>
        <collision>
            <origin xyz="-6.27876e-17 -1.94611e-17 0.0235" rpy="-2.44036e-16 -1.95133e-16 9.01467e-18"/>
            <geometry>
                <sphere radius="0.014"/>
            </geometry>
        </collision>
        <collision>
            <origin xyz="-2.79607e-17 -3.63275e-17 -0.0235" rpy="-2.44036e-16 -1.95133e-16 9.01467e-18"/>
            <geometry>
                <sphere radius="0.014"/>
            </geometry>
        </collision>
        <visual>
            <origin xyz="1.38778e-16 -1.66533e-16 -4.16334e-16" rpy="-2.3491 0.118587 1.30549"/>
            <geometry>
                <mesh filename="package://assets/merged/roller_4_visual.stl"/>
            </geometry>
            <material name="roller_4_parts_material">
                <color rgba="0.752941 0.752941 0.752941 1.0"/>
            </material>
        </visual>
    </link>
    <!-- Joint from front_right_wheel to roller_4 -->
    <joint name="frw_r4" type="revolute">
        <origin xyz="-0.0847877 -0.014389 -0.039" rpy="-2.78255 -0.714734 -1.92274"/>
        <parent link="front_right_wheel"/>
        <child link="roller_4"/>
        <axis xyz="0 0 1"/>
        <limit effort="10" velocity="10" lower="-3.141592653589793" upper="3.141592653589793"/>
    </joint>
    <!-- Link roller_5 -->
    <link name="roller_5">
        <inertial>
            <origin xyz="1.60744e-16 -1.97658e-16 -3.92708e-16" rpy="0 0 0"/>
            <mass value="0.0493467"/>
            <inertia ixx="1.86522e-05" ixy="-1.05201e-22" ixz="8.40012e-22" iyy="1.86522e-05" iyz="-4.26945e-21" izz="5.80503e-06"/>
        </inertial>
        <!-- Part roller_5_parts -->
        <collision>
            <origin xyz="-1.30364e-17 -5.80112e-17 -1.59417e-16" rpy="-2.77184e-16 -1.11197e-16 7.15497e-17"/>
            <geometry>
                <sphere radius="0.0155"/>
            </geometry>
        </collision>
        <collision>
            <origin xyz="3.65064e-18 -7.55904e-17 0.0085" rpy="-2.77184e-16 -1.11197e-16 7.15497e-17"/>
            <geometry>
                <sphere radius="0.0155"/>
            </geometry>
        </collision>
        <collision>
            <origin xyz="-2.94112e-17 -4.04885e-17 -0.0085" rpy="-2.77184e-16 -1.11197e-16 7.15497e-17"/>
            <geometry>
                <sphere radius="0.0155"/>
            </geometry>
        </collision>
        <collision>
            <origin xyz="-1.62441e-17 -7.53745e-17 0.0165" rpy="-2.77184e-16 -1.11197e-16 7.15497e-17"/>
            <geometry>
                <sphere radius="0.015"/>
            </geometry>
        </collision>
        <collision>
            <origin xyz="-1.08073e-17 -4.11586e-17 -0.0165" rpy="-2.77184e-16 -1.11197e-16 7.15497e-17"/>
            <geometry>
                <sphere radius="0.015"/>
            </geometry>
        </collision>
        <collision>
            <origin xyz="-6.65158e-18 -3.52675e-17 0.0235" rpy="-2.77184e-16 -1.11197e-16 7.15497e-17"/>
            <geometry>
                <sphere radius="0.014"/>
            </geometry>
        </collision>
        <collision>
            <origin xyz="-1.86854e-17 -7.99235e-17 -0.0235" rpy="-2.77184e-16 -1.11197e-16 7.15497e-17"/>
            <geometry>
                <sphere radius="0.014"/>
            </geometry>
        </collision>
        <visual>
            <origin xyz="1.66533e-16 -1.66533e-16 -4.23273e-16" rpy="-2.22708 0.467917 1.71585"/>
            <geometry>
                <mesh filename="package://assets/merged/roller_5_visual.stl"/>
            </geometry>
            <material name="roller_5_parts_material">
                <color rgba="0.752941 0.752941 0.752941 1.0"/>
            </material>
        </visual>
    </link>
    <!-- Joint from front_right_wheel to roller_5 -->
    <joint name="frw_r5" type="revolute">
        <origin xyz="-0.0662338 -0.0548551 -0.039" rpy="-2.78255 -0.714734 -1.39914"/>
        <parent link="front_right_wheel"/>
        <child link="roller_5"/>
        <axis xyz="0 0 1"/>
        <limit effort="10" velocity="10" lower="-3.141592653589793" upper="3.141592653589793"/>
    </joint>
    <!-- Link roller_6 -->
    <link name="roller_6">
        <inertial>
            <origin xyz="1.04736e-16 -1.66598e-16 -4.10463e-16" rpy="0 0 0"/>
            <mass value="0.0493467"/>
            <inertia ixx="1.86522e-05" ixy="1.17059e-21" ixz="1.29645e-21" iyy="1.86522e-05" iyz="-2.83497e-21" izz="5.80503e-06"/>
        </inertial>
        <!-- Part roller_6_parts -->
        <collision>
            <origin xyz="-6.90444e-17 -2.69512e-17 -1.77173e-16" rpy="-1.44829e-16 -9.77465e-17 -6.993e-17"/>
            <geometry>
                <sphere radius="0.0155"/>
            </geometry>
        </collision>
        <collision>
            <origin xyz="-7.5503e-17 -1.87819e-17 0.0085" rpy="-1.44829e-16 -9.77465e-17 -6.993e-17"/>
            <geometry>
                <sphere radius="0.0155"/>
            </geometry>
        </collision>
        <collision>
            <origin xyz="-6.14842e-17 -3.38299e-17 -0.0085" rpy="-1.44829e-16 -9.77465e-17 -6.993e-17"/>
            <geometry>
                <sphere radius="0.0155"/>
            </geometry>
        </collision>
        <collision>
            <origin xyz="-7.44392e-17 -1.76205e-17 0.0165" rpy="-1.44829e-16 -9.77465e-17 -6.993e-17"/>
            <geometry>
                <sphere radius="0.015"/>
            </geometry>
        </collision>
        <collision>
            <origin xyz="-6.33372e-17 -3.61215e-17 -0.0165" rpy="-1.44829e-16 -9.77465e-17 -6.993e-17"/>
            <geometry>
                <sphere radius="0.015"/>
            </geometry>
        </collision>
        <collision>
            <origin xyz="-5.92588e-17 -2.89216e-17 0.0235" rpy="-1.44829e-16 -9.77465e-17 -6.993e-17"/>
            <geometry>
                <sphere radius="0.014"/>
            </geometry>
        </collision>
        <collision>
            <origin xyz="-7.89514e-17 -2.48205e-17 -0.0235" rpy="-1.44829e-16 -9.77465e-17 -6.993e-17"/>
            <geometry>
                <sphere radius="0.014"/>
            </geometry>
        </collision>
        <visual>
            <origin xyz="1.11022e-16 -1.66533e-16 -4.2891e-16" rpy="-1.90574 0.724678 2.27337"/>
            <geometry>
                <mesh filename="package://assets/merged/roller_6_visual.stl"/>
            </geometry>
            <material name="roller_6_parts_material">
                <color rgba="0.752941 0.752941 0.752941 1.0"/>
            </material>
        </visual>
    </link>
    <!-- Joint from front_right_wheel to roller_6 -->
    <joint name="frw_r6" type="revolute">
        <origin xyz="-0.0299326 -0.0806228 -0.039" rpy="-2.78255 -0.714734 -0.875544"/>
        <parent link="front_right_wheel"/>
        <child link="roller_6"/>
        <axis xyz="0 0 1"/>
        <limit effort="10" velocity="10" lower="-3.141592653589793" upper="3.141592653589793"/>
    </joint>
    <!-- Link roller_7 -->
    <link name="roller_7">
        <inertial>
            <origin xyz="1.18736e-16 -1.21936e-16 -4.42173e-16" rpy="0 0 0"/>
            <mass value="0.0493467"/>
            <inertia ixx="1.86522e-05" ixy="-1.27401e-21" ixz="1.83206e-21" iyy="1.86522e-05" iyz="-3.43584e-21" izz="5.80503e-06"/>
        </inertial>
        <!-- Part roller_7_parts -->
        <collision>
            <origin xyz="-5.50448e-17 1.77109e-17 -2.08883e-16" rpy="-2.27238e-16 -1.06483e-16 -1.52475e-17"/>
            <geometry>
                <sphere radius="0.0155"/>
            </geometry>
        </collision>
        <collision>
            <origin xyz="-5.98375e-17 2.16803e-17 0.0085" rpy="-2.27238e-16 -1.06483e-16 -1.52475e-17"/>
            <geometry>
                <sphere radius="0.0155"/>
            </geometry>
        </collision>
        <collision>
            <origin xyz="-4.96081e-17 1.36779e-17 -0.0085" rpy="-2.27238e-16 -1.06483e-16 -1.52475e-17"/>
            <geometry>
                <sphere radius="0.0155"/>
            </geometry>
        </collision>
        <collision>
            <origin xyz="-3.13163e-17 1.10115e-17 0.0165" rpy="-2.27238e-16 -1.06483e-16 -1.52475e-17"/>
            <geometry>
                <sphere radius="0.015"/>
            </geometry>
        </collision>
        <collision>
            <origin xyz="-7.89967e-17 2.4455e-17 -0.0165" rpy="-2.27238e-16 -1.06483e-16 -1.52475e-17"/>
            <geometry>
                <sphere radius="0.015"/>
            </geometry>
        </collision>
        <collision>
            <origin xyz="-7.84033e-17 2.74169e-17 0.0235" rpy="-2.27238e-16 -1.06483e-16 -1.52475e-17"/>
            <geometry>
                <sphere radius="0.014"/>
            </geometry>
        </collision>
        <collision>
            <origin xyz="-3.19097e-17 7.83279e-18 -0.0235" rpy="-2.27238e-16 -1.06483e-16 -1.52475e-17"/>
            <geometry>
                <sphere radius="0.014"/>
            </geometry>
        </collision>
        <visual>
            <origin xyz="1.11022e-16 -1.249e-16 -4.16334e-16" rpy="-1.40502 0.771399 -0.149186"/>
            <geometry>
                <mesh filename="package://assets/merged/roller_7_visual.stl"/>
            </geometry>
            <material name="roller_7_parts_material">
                <color rgba="0.752941 0.752941 0.752941 1.0"/>
            </material>
        </visual>
    </link>
    <!-- Joint from front_right_wheel to roller_7 -->
    <joint name="frw_r7" type="revolute">
        <origin xyz="0.014389 -0.0847877 -0.039" rpy="2.78255 0.714734 2.78965"/>
        <parent link="front_right_wheel"/>
        <child link="roller_7"/>
        <axis xyz="0 0 1"/>
        <limit effort="10" velocity="10" lower="-3.141592653589793" upper="3.141592653589793"/>
    </joint>
    <!-- Link roller_8 -->
    <link name="roller_8">
        <inertial>
            <origin xyz="2.18847e-16 -1.22285e-16 -4.16685e-16" rpy="0 0 0"/>
            <mass value="0.0493467"/>
            <inertia ixx="1.86522e-05" ixy="-2.26387e-21" ixz="8.26688e-22" iyy="1.86522e-05" iyz="-3.08214e-21" izz="5.80503e-06"/>
        </inertial>
        <!-- Part roller_8_parts -->
        <collision>
            <origin xyz="4.50668e-17 1.73622e-17 -1.83395e-16" rpy="-2.88582e-16 -5.40372e-17 4.93335e-17"/>
            <geometry>
                <sphere radius="0.0155"/>
            </geometry>
        </collision>
        <collision>
            <origin xyz="3.37472e-17 1.81774e-17 0.0085" rpy="-2.88582e-16 -5.40372e-17 4.93335e-17"/>
            <geometry>
                <sphere radius="0.0155"/>
            </geometry>
        </collision>
        <collision>
            <origin xyz="5.62885e-17 1.68086e-17 -0.0085" rpy="-2.88582e-16 -5.40372e-17 4.93335e-17"/>
            <geometry>
                <sphere radius="0.0155"/>
            </geometry>
        </collision>
        <collision>
            <origin xyz="5.08733e-17 9.78022e-18 0.0165" rpy="-2.88582e-16 -5.40372e-17 4.93335e-17"/>
            <geometry>
                <sphere radius="0.015"/>
            </geometry>
        </collision>
        <collision>
            <origin xyz="3.88406e-17 2.44398e-17 -0.0165" rpy="-2.88582e-16 -5.40372e-17 4.93335e-17"/>
            <geometry>
                <sphere radius="0.015"/>
            </geometry>
        </collision>
        <collision>
            <origin xyz="5.38336e-17 1.2327e-17 0.0235" rpy="-2.88582e-16 -5.40372e-17 4.93335e-17"/>
            <geometry>
                <sphere radius="0.014"/>
            </geometry>
        </collision>
        <collision>
            <origin xyz="3.78389e-17 2.12284e-17 -0.0235" rpy="-2.88582e-16 -5.40372e-17 4.93335e-17"/>
            <geometry>
                <sphere radius="0.014"/>
            </geometry>
        </collision>
        <visual>
            <origin xyz="2.22045e-16 -1.29237e-16 -4.02456e-16" rpy="-1.00301 0.575895 0.479378"/>
            <geometry>
                <mesh filename="package://assets/merged/roller_8_visual.stl"/>
            </geometry>
            <material name="roller_8_parts_material">
                <color rgba="0.752941 0.752941 0.752941 1.0"/>
            </material>
        </visual>
    </link>
    <!-- Joint from front_right_wheel to roller_8 -->
    <joint name="frw_r8" type="revolute">
        <origin xyz="0.0548551 -0.0662338 -0.039" rpy="2.78255 0.714734 -2.96994"/>
        <parent link="front_right_wheel"/>
        <child link="roller_8"/>
        <axis xyz="0 0 1"/>
        <limit effort="10" velocity="10" lower="-3.141592653589793" upper="3.141592653589793"/>
    </joint>
    <!-- Link roller_9 -->
    <link name="roller_9">
        <inertial>
            <origin xyz="2.12561e-16 -1.15357e-16 -4.01217e-16" rpy="0 0 0"/>
            <mass value="0.0493467"/>
            <inertia ixx="1.86522e-05" ixy="-4.5281e-22" ixz="1.98402e-22" iyy="1.86522e-05" iyz="-1.94045e-21" izz="5.80503e-06"/>
        </inertial>
        <!-- Part roller_9_parts -->
        <collision>
            <origin xyz="3.87808e-17 2.42894e-17 -1.67927e-16" rpy="-1.47754e-16 -5.98053e-17 -4.30137e-17"/>
            <geometry>
                <sphere radius="0.0155"/>
            </geometry>
        </collision>
        <collision>
            <origin xyz="1.82816e-17 2.54745e-17 0.0085" rpy="-1.47754e-16 -5.98053e-17 -4.30137e-17"/>
            <geometry>
                <sphere radius="0.0155"/>
            </geometry>
        </collision>
        <collision>
            <origin xyz="5.94842e-17 2.30191e-17 -0.0085" rpy="-1.47754e-16 -5.98053e-17 -4.30137e-17"/>
            <geometry>
                <sphere radius="0.0155"/>
            </geometry>
        </collision>
        <collision>
            <origin xyz="2.4517e-17 1.75409e-17 0.0165" rpy="-1.47754e-16 -5.98053e-17 -4.30137e-17"/>
            <geometry>
                <sphere radius="0.015"/>
            </geometry>
        </collision>
        <collision>
            <origin xyz="5.32488e-17 3.0519e-17 -0.0165" rpy="-1.47754e-16 -5.98053e-17 -4.30137e-17"/>
            <geometry>
                <sphere radius="0.015"/>
            </geometry>
        </collision>
        <collision>
            <origin xyz="6.14411e-17 2.81476e-17 0.0235" rpy="-1.47754e-16 -5.98053e-17 -4.30137e-17"/>
            <geometry>
                <sphere radius="0.014"/>
            </geometry>
        </collision>
        <collision>
            <origin xyz="1.63247e-17 1.99123e-17 -0.0235" rpy="-1.47754e-16 -5.98053e-17 -4.30137e-17"/>
            <geometry>
                <sphere radius="0.014"/>
            </geometry>
        </collision>
        <visual>
            <origin xyz="2.22045e-16 -1.11022e-16 -3.88578e-16" rpy="-0.817659 0.248666 0.929333"/>
            <geometry>
                <mesh filename="package://assets/merged/roller_9_visual.stl"/>
            </geometry>
            <material name="roller_9_parts_material">
                <color rgba="0.752941 0.752941 0.752941 1.0"/>
            </material>
        </visual>
    </link>
    <!-- Joint from front_right_wheel to roller_9 -->
    <joint name="frw_r9" type="revolute">
        <origin xyz="0.0806228 -0.0299326 -0.039" rpy="2.78255 0.714734 -2.44634"/>
        <parent link="front_right_wheel"/>
        <child link="roller_9"/>
        <axis xyz="0 0 1"/>
        <limit effort="10" velocity="10" lower="-3.141592653589793" upper="3.141592653589793"/>
    </joint>
    <!-- Link roller_10 -->
    <link name="roller_10">
        <inertial>
            <origin xyz="1.80518e-16 -1.25627e-16 -3.95889e-16" rpy="0 0 0"/>
            <mass value="0.0493467"/>
            <inertia ixx="1.86522e-05" ixy="8.02219e-22" ixz="4.97481e-21" iyy="1.86522e-05" iyz="-3.20162e-21" izz="5.80503e-06"/>
        </inertial>
        <!-- Part roller_10_parts -->
        <collision>
            <origin xyz="6.73739e-18 1.40195e-17 -1.62599e-16" rpy="-2.29852e-16 -2.48923e-16 -3.78728e-18"/>
            <geometry>
                <sphere radius="0.0155"/>
            </geometry>
        </collision>
        <collision>
            <origin xyz="1.00047e-17 1.34011e-17 0.0085" rpy="-2.29852e-16 -2.48923e-16 -3.78728e-18"/>
            <geometry>
                <sphere radius="0.0155"/>
            </geometry>
        </collision>
        <collision>
            <origin xyz="3.77193e-18 1.46957e-17 -0.0085" rpy="-2.29852e-16 -2.48923e-16 -3.78728e-18"/>
            <geometry>
                <sphere radius="0.0155"/>
            </geometry>
        </collision>
        <collision>
            <origin xyz="4.40127e-18 2.89128e-17 0.0165" rpy="-2.29852e-16 -2.48923e-16 -3.78728e-18"/>
            <geometry>
                <sphere radius="0.015"/>
            </geometry>
        </collision>
        <collision>
            <origin xyz="8.50801e-18 -9.24488e-19 -0.0165" rpy="-2.29852e-16 -2.48923e-16 -3.78728e-18"/>
            <geometry>
                <sphere radius="0.015"/>
            </geometry>
        </collision>
        <collision>
            <origin xyz="-6.79676e-18 9.91667e-18 0.0235" rpy="-2.29852e-16 -2.48923e-16 -3.78728e-18"/>
            <geometry>
                <sphere radius="0.014"/>
            </geometry>
        </collision>
        <collision>
            <origin xyz="1.9706e-17 1.82885e-17 -0.0235" rpy="-2.29852e-16 -2.48923e-16 -3.78728e-18"/>
            <geometry>
                <sphere radius="0.014"/>
            </geometry>
        </collision>
        <visual>
            <origin xyz="1.94289e-16 -1.249e-16 -3.88578e-16" rpy="-0.792496 -0.118587 1.30549"/>
            <geometry>
                <mesh filename="package://assets/merged/roller_10_visual.stl"/>
            </geometry>
            <material name="roller_10_parts_material">
                <color rgba="0.752941 0.752941 0.752941 1.0"/>
            </material>
        </visual>
    </link>
    <!-- Joint from front_right_wheel to roller_10 -->
    <joint name="frw_r10" type="revolute">
        <origin xyz="0.0847877 0.014389 -0.039" rpy="2.78255 0.714734 -1.92274"/>
        <parent link="front_right_wheel"/>
        <child link="roller_10"/>
        <axis xyz="0 0 1"/>
        <limit effort="10" velocity="10" lower="-3.141592653589793" upper="3.141592653589793"/>
    </joint>
    <!-- Link roller_11 -->
    <link name="roller_11">
        <inertial>
            <origin xyz="1.76845e-16 -1.27599e-16 -4.0969e-16" rpy="0 0 0"/>
            <mass value="0.0493467"/>
            <inertia ixx="1.86522e-05" ixy="-2.79336e-21" ixz="1.03684e-21" iyy="1.86522e-05" iyz="-1.94483e-21" izz="5.80503e-06"/>
        </inertial>
        <!-- Part roller_11_parts -->
        <collision>
            <origin xyz="3.06506e-18 1.20481e-17 -1.764e-16" rpy="-1.87322e-16 -3.37222e-17 -4.14957e-17"/>
            <geometry>
                <sphere radius="0.0155"/>
            </geometry>
        </collision>
        <collision>
            <origin xyz="-6.70312e-18 4.55608e-18 0.0085" rpy="-1.87322e-16 -3.37222e-17 -4.14957e-17"/>
            <geometry>
                <sphere radius="0.0155"/>
            </geometry>
        </collision>
        <collision>
            <origin xyz="1.28158e-17 1.93664e-17 -0.0085" rpy="-1.87322e-16 -3.37222e-17 -4.14957e-17"/>
            <geometry>
                <sphere radius="0.0155"/>
            </geometry>
        </collision>
        <collision>
            <origin xyz="-5.60659e-18 3.2815e-18 0.0165" rpy="-1.87322e-16 -3.37222e-17 -4.14957e-17"/>
            <geometry>
                <sphere radius="0.015"/>
            </geometry>
        </collision>
        <collision>
            <origin xyz="1.70877e-17 9.87992e-18 -0.0165" rpy="-1.87322e-16 -3.37222e-17 -4.14957e-17"/>
            <geometry>
                <sphere radius="0.015"/>
            </geometry>
        </collision>
        <collision>
            <origin xyz="-6.76211e-18 -1.50631e-18 0.0235" rpy="-1.87322e-16 -3.37222e-17 -4.14957e-17"/>
            <geometry>
                <sphere radius="0.014"/>
            </geometry>
        </collision>
        <collision>
            <origin xyz="1.91106e-17 1.38004e-17 -0.0235" rpy="-1.87322e-16 -3.37222e-17 -4.14957e-17"/>
            <geometry>
                <sphere radius="0.014"/>
            </geometry>
        </collision>
        <visual>
            <origin xyz="1.94289e-16 -1.249e-16 -3.88578e-16" rpy="-0.914517 -0.467917 0.145054"/>
            <geometry>
                <mesh filename="package://assets/merged/roller_11_visual.stl"/>
            </geometry>
            <material name="roller_11_parts_material">
                <color rgba="0.752941 0.752941 0.752941 1.0"/>
            </material>
        </visual>
    </link>
    <!-- Joint from front_right_wheel to roller_11 -->
    <joint name="frw_r11" type="revolute">
        <origin xyz="0.0662338 0.0548551 -0.039" rpy="2.39411 -0.268603 -2.72874"/>
        <parent link="front_right_wheel"/>
        <child link="roller_11"/>
        <axis xyz="0 0 1"/>
        <limit effort="10" velocity="10" lower="-3.141592653589793" upper="3.141592653589793"/>
    </joint>
    <!-- Link roller_12 -->
    <link name="roller_12">
        <inertial>
            <origin xyz="1.79562e-16 -1.85077e-16 -3.45947e-16" rpy="0 0 0"/>
            <mass value="0.0493467"/>
            <inertia ixx="1.86522e-05" ixy="-5.49066e-22" ixz="1.64767e-21" iyy="1.86522e-05" iyz="-2.89764e-21" izz="5.80503e-06"/>
        </inertial>
        <!-- Part roller_12_parts -->
        <collision>
            <origin xyz="5.78159e-18 -4.54301e-17 -1.12657e-16" rpy="-2.0113e-16 -5.83762e-17 -3.79602e-17"/>
            <geometry>
                <sphere radius="0.0155"/>
            </geometry>
        </collision>
        <collision>
            <origin xyz="5.42013e-18 -4.75153e-17 0.0085" rpy="-2.0113e-16 -5.83762e-17 -3.79602e-17"/>
            <geometry>
                <sphere radius="0.0155"/>
            </geometry>
        </collision>
        <collision>
            <origin xyz="6.28146e-18 -4.3621e-17 -0.0085" rpy="-2.0113e-16 -5.83762e-17 -3.79602e-17"/>
            <geometry>
                <sphere radius="0.0155"/>
            </geometry>
        </collision>
        <collision>
            <origin xyz="-1.77616e-18 -4.64367e-17 0.0165" rpy="-2.0113e-16 -5.83762e-17 -3.79602e-17"/>
            <geometry>
                <sphere radius="0.015"/>
            </geometry>
        </collision>
        <collision>
            <origin xyz="1.39114e-17 -4.44828e-17 -0.0165" rpy="-2.0113e-16 -5.83762e-17 -3.79602e-17"/>
            <geometry>
                <sphere radius="0.015"/>
            </geometry>
        </collision>
        <collision>
            <origin xyz="-7.5417e-18 -4.86307e-17 0.0235" rpy="-2.0113e-16 -5.83762e-17 -3.79602e-17"/>
            <geometry>
                <sphere radius="0.014"/>
            </geometry>
        </collision>
        <collision>
            <origin xyz="1.88096e-17 -4.18551e-17 -0.0235" rpy="-2.0113e-16 -5.83762e-17 -3.79602e-17"/>
            <geometry>
                <sphere radius="0.014"/>
            </geometry>
        </collision>
        <visual>
            <origin xyz="1.8735e-16 -1.8735e-16 -3.33067e-16" rpy="-1.23586 -0.724678 0.702578"/>
            <geometry>
                <mesh filename="package://assets/merged/roller_12_visual.stl"/>
            </geometry>
            <material name="roller_12_parts_material">
                <color rgba="0.752941 0.752941 0.752941 1.0"/>
            </material>
        </visual>
    </link>
    <!-- Joint from front_right_wheel to roller_12 -->
    <joint name="frw_r12" type="revolute">
        <origin xyz="0.0299326 0.0806228 -0.039" rpy="2.39411 -0.268603 -2.20514"/>
        <parent link="front_right_wheel"/>
        <child link="roller_12"/>
        <axis xyz="0 0 1"/>
        <limit effort="10" velocity="10" lower="-3.141592653589793" upper="3.141592653589793"/>
    </joint>
    <!-- Joint from base_link to front_right_wheel -->
    <joint name="front_right_wheel" type="continuous">
        <origin xyz="0.2685 -0.24 0.065" rpy="1.5708 8.40537e-15 -3.14159"/>
        <parent link="base_link"/>
        <child link="front_right_wheel"/>
        <axis xyz="0 0 1"/>
        <limit effort="10" velocity="10"/>
    </joint>
    <!-- Link back_left_wheel -->
    <link name="back_left_wheel">
        <inertial>
            <origin xyz="2.30268e-06 -1.35714e-05 0.038998" rpy="0 0 0"/>
            <mass value="0.942157"/>
            <inertia ixx="0.00202095" ixy="-9.2256e-07" ixz="-8.13728e-12" iyy="0.00202623" iyz="2.75701e-11" izz="0.00255146"/>
        </inertial>
        <!-- Part back_left_wheel_parts -->
        <visual>
            <origin xyz="2.30268e-06 -1.35714e-05 0.038998" rpy="1.5708 3.62788e-15 -3.14159"/>
            <geometry>
                <mesh filename="package://assets/merged/back_left_wheel_visual.stl"/>
            </geometry>
            <material name="back_left_wheel_parts_material">
                <color rgba="0.792157 0.819608 0.933333 1.0"/>
            </material>
        </visual>
    </link>
    <!-- Link roller_13 -->
    <link name="roller_13">
        <inertial>
            <origin xyz="1.86501e-16 -1.50382e-16 -2.90436e-16" rpy="0 0 0"/>
            <mass value="0.0493467"/>
            <inertia ixx="1.86522e-05" ixy="-1.51027e-21" ixz="-3.28315e-22" iyy="1.86522e-05" iyz="-2.35557e-21" izz="5.80503e-06"/>
        </inertial>
        <!-- Part roller_13_parts -->
        <collision>
            <origin xyz="1.27205e-17 -1.07357e-17 -5.71455e-17" rpy="-2.03443e-16 4.23158e-18 4.39102e-17"/>
            <geometry>
                <sphere radius="0.0155"/>
            </geometry>
        </collision>
        <collision>
            <origin xyz="2.04945e-17 -2.21557e-17 0.0085" rpy="-2.03443e-16 4.23158e-18 4.39102e-17"/>
            <geometry>
                <sphere radius="0.0155"/>
            </geometry>
        </collision>
        <collision>
            <origin xyz="5.08485e-18 8.42005e-19 -0.0085" rpy="-2.03443e-16 4.23158e-18 4.39102e-17"/>
            <geometry>
                <sphere radius="0.0155"/>
            </geometry>
        </collision>
        <collision>
            <origin xyz="9.94688e-18 6.05841e-19 0.0165" rpy="-2.03443e-16 4.23158e-18 4.39102e-17"/>
            <geometry>
                <sphere radius="0.015"/>
            </geometry>
        </collision>
        <collision>
            <origin xyz="1.51988e-17 -2.21364e-17 -0.0165" rpy="-2.03443e-16 4.23158e-18 4.39102e-17"/>
            <geometry>
                <sphere radius="0.015"/>
            </geometry>
        </collision>
        <collision>
            <origin xyz="1.91876e-17 -4.73071e-19 0.0235" rpy="-2.03443e-16 4.23158e-18 4.39102e-17"/>
            <geometry>
                <sphere radius="0.014"/>
            </geometry>
        </collision>
        <collision>
            <origin xyz="7.6928e-18 -2.06238e-17 -0.0235" rpy="-2.03443e-16 4.23158e-18 4.39102e-17"/>
            <geometry>
                <sphere radius="0.014"/>
            </geometry>
        </collision>
        <visual>
            <origin xyz="1.94289e-16 -1.52656e-16 -2.77556e-16" rpy="-1.23586 -0.724678 0.702578"/>
            <geometry>
                <mesh filename="package://assets/merged/roller_13_visual.stl"/>
            </geometry>
            <material name="roller_13_parts_material">
                <color rgba="0.752941 0.752941 0.752941 1.0"/>
            </material>
        </visual>
    </link>
    <!-- Joint from back_left_wheel to roller_13 -->
    <joint name="blw_r1" type="revolute">
        <origin xyz="0.0299314 0.0806297 0.039" rpy="2.39411 -0.268603 -2.20514"/>
        <parent link="back_left_wheel"/>
        <child link="roller_13"/>
        <axis xyz="0 0 1"/>
        <limit effort="10" velocity="10" lower="-3.141592653589793" upper="3.141592653589793"/>
    </joint>
    <!-- Link roller_14 -->
    <link name="roller_14">
        <inertial>
            <origin xyz="1.4909e-16 -1.13721e-16 -3.54179e-16" rpy="0 0 0"/>
            <mass value="0.0493467"/>
            <inertia ixx="1.86522e-05" ixy="2.22238e-21" ixz="-5.07406e-22" iyy="1.86522e-05" iyz="-1.33348e-21" izz="5.80503e-06"/>
        </inertial>
        <!-- Part roller_14_parts -->
        <collision>
            <origin xyz="-2.46905e-17 2.59259e-17 -1.20889e-16" rpy="-1.19378e-16 -1.15773e-17 7.01011e-17"/>
            <geometry>
                <sphere radius="0.0155"/>
            </geometry>
        </collision>
        <collision>
            <origin xyz="-3.12355e-17 2.6135e-17 0.0085" rpy="-1.19378e-16 -1.15773e-17 7.01011e-17"/>
            <geometry>
                <sphere radius="0.0155"/>
            </geometry>
        </collision>
        <collision>
            <origin xyz="-1.81629e-17 2.59768e-17 -0.0085" rpy="-1.19378e-16 -1.15773e-17 7.01011e-17"/>
            <geometry>
                <sphere radius="0.0155"/>
            </geometry>
        </collision>
        <collision>
            <origin xyz="-3.02189e-17 3.76637e-17 0.0165" rpy="-1.19378e-16 -1.15773e-17 7.01011e-17"/>
            <geometry>
                <sphere radius="0.015"/>
            </geometry>
        </collision>
        <collision>
            <origin xyz="-1.91796e-17 1.44481e-17 -0.0165" rpy="-1.19378e-16 -1.15773e-17 7.01011e-17"/>
            <geometry>
                <sphere radius="0.015"/>
            </geometry>
        </collision>
        <collision>
            <origin xyz="-2.9275e-17 3.43614e-17 0.0235" rpy="-1.19378e-16 -1.15773e-17 7.01011e-17"/>
            <geometry>
                <sphere radius="0.014"/>
            </geometry>
        </collision>
        <collision>
            <origin xyz="-1.56224e-17 7.42297e-18 -0.0235" rpy="-1.19378e-16 -1.15773e-17 7.01011e-17"/>
            <geometry>
                <sphere radius="0.014"/>
            </geometry>
        </collision>
        <visual>
            <origin xyz="1.66533e-16 -1.11022e-16 -3.33067e-16" rpy="-0.914517 -0.467917 0.145054"/>
            <geometry>
                <mesh filename="package://assets/merged/roller_14_visual.stl"/>
            </geometry>
            <material name="roller_14_parts_material">
                <color rgba="0.752941 0.752941 0.752941 1.0"/>
            </material>
        </visual>
    </link>
    <!-- Joint from back_left_wheel to roller_14 -->
    <joint name="blw_r2" type="revolute">
        <origin xyz="0.0662326 0.054862 0.039" rpy="2.39411 -0.268603 -2.72874"/>
        <parent link="back_left_wheel"/>
        <child link="roller_14"/>
        <axis xyz="0 0 1"/>
        <limit effort="10" velocity="10" lower="-3.141592653589793" upper="3.141592653589793"/>
    </joint>
    <!-- Link roller_15 -->
    <link name="roller_15">
        <inertial>
            <origin xyz="1.52762e-16 -1.67261e-16 -4.23645e-16" rpy="0 0 0"/>
            <mass value="0.0493467"/>
            <inertia ixx="1.86522e-05" ixy="-4.68824e-22" ixz="4.84476e-22" iyy="1.86522e-05" iyz="-2.42134e-21" izz="5.80503e-06"/>
        </inertial>
        <!-- Part roller_15_parts -->
        <collision>
            <origin xyz="-2.10182e-17 -2.76139e-17 -1.90354e-16" rpy="-1.83978e-16 -1.86094e-16 1.16229e-18"/>
            <geometry>
                <sphere radius="0.0155"/>
            </geometry>
        </collision>
        <collision>
            <origin xyz="-3.70176e-17 -4.58427e-17 0.0085" rpy="-1.83978e-16 -1.86094e-16 1.16229e-18"/>
            <geometry>
                <sphere radius="0.0155"/>
            </geometry>
        </collision>
        <collision>
            <origin xyz="-4.71693e-18 -9.32724e-18 -0.0085" rpy="-1.83978e-16 -1.86094e-16 1.16229e-18"/>
            <geometry>
                <sphere radius="0.0155"/>
            </geometry>
        </collision>
        <collision>
            <origin xyz="-6.46306e-18 -1.00411e-17 0.0165" rpy="-1.83978e-16 -1.86094e-16 1.16229e-18"/>
            <geometry>
                <sphere radius="0.015"/>
            </geometry>
        </collision>
        <collision>
            <origin xyz="-3.44041e-17 -4.52373e-17 -0.0165" rpy="-1.83978e-16 -1.86094e-16 1.16229e-18"/>
            <geometry>
                <sphere radius="0.015"/>
            </geometry>
        </collision>
        <collision>
            <origin xyz="-3.66179e-17 -4.67186e-17 0.0235" rpy="-1.83978e-16 -1.86094e-16 1.16229e-18"/>
            <geometry>
                <sphere radius="0.014"/>
            </geometry>
        </collision>
        <collision>
            <origin xyz="-5.98398e-18 -8.34295e-18 -0.0235" rpy="-1.83978e-16 -1.86094e-16 1.16229e-18"/>
            <geometry>
                <sphere radius="0.014"/>
            </geometry>
        </collision>
        <visual>
            <origin xyz="1.66533e-16 -1.66533e-16 -4.16334e-16" rpy="-0.792496 -0.118587 1.30549"/>
            <geometry>
                <mesh filename="package://assets/merged/roller_15_visual.stl"/>
            </geometry>
            <material name="roller_15_parts_material">
                <color rgba="0.752941 0.752941 0.752941 1.0"/>
            </material>
        </visual>
    </link>
    <!-- Joint from back_left_wheel to roller_15 -->
    <joint name="blw_r3" type="revolute">
        <origin xyz="0.0847865 0.0143959 0.039" rpy="2.78255 0.714734 -1.92274"/>
        <parent link="back_left_wheel"/>
        <child link="roller_15"/>
        <axis xyz="0 0 1"/>
        <limit effort="10" velocity="10" lower="-3.141592653589793" upper="3.141592653589793"/>
    </joint>
    <!-- Link roller_16 -->
    <link name="roller_16">
        <inertial>
            <origin xyz="2.12561e-16 -5.98462e-17 -3.59584e-16" rpy="0 0 0"/>
            <mass value="0.0493467"/>
            <inertia ixx="1.86522e-05" ixy="-2.28019e-21" ixz="1.40144e-21" iyy="1.86522e-05" iyz="-4.15489e-22" izz="5.80503e-06"/>
        </inertial>
        <!-- Part roller_16_parts -->
        <collision>
            <origin xyz="3.87808e-17 7.98005e-17 -1.26294e-16" rpy="-1.99323e-16 -8.59392e-17 -5.59826e-17"/>
            <geometry>
                <sphere radius="0.0155"/>
            </geometry>
        </collision>
        <collision>
            <origin xyz="3.15991e-17 6.54532e-17 0.0085" rpy="-1.99323e-16 -8.59392e-17 -5.59826e-17"/>
            <geometry>
                <sphere radius="0.0155"/>
            </geometry>
        </collision>
        <collision>
            <origin xyz="4.61667e-17 9.44964e-17 -0.0085" rpy="-1.99323e-16 -8.59392e-17 -5.59826e-17"/>
            <geometry>
                <sphere radius="0.0155"/>
            </geometry>
        </collision>
        <collision>
            <origin xyz="4.28516e-17 1.05562e-16 0.0165" rpy="-1.99323e-16 -8.59392e-17 -5.59826e-17"/>
            <geometry>
                <sphere radius="0.015"/>
            </geometry>
        </collision>
        <collision>
            <origin xyz="3.32356e-17 5.63699e-17 -0.0165" rpy="-1.99323e-16 -8.59392e-17 -5.59826e-17"/>
            <geometry>
                <sphere radius="0.015"/>
            </geometry>
        </collision>
        <collision>
            <origin xyz="3.63081e-17 1.01286e-16 0.0235" rpy="-1.99323e-16 -8.59392e-17 -5.59826e-17"/>
            <geometry>
                <sphere radius="0.014"/>
            </geometry>
        </collision>
        <collision>
            <origin xyz="4.14577e-17 5.77965e-17 -0.0235" rpy="-1.99323e-16 -8.59392e-17 -5.59826e-17"/>
            <geometry>
                <sphere radius="0.014"/>
            </geometry>
        </collision>
        <visual>
            <origin xyz="2.22045e-16 -5.55112e-17 -3.46945e-16" rpy="-0.817659 0.248666 0.929333"/>
            <geometry>
                <mesh filename="package://assets/merged/roller_16_visual.stl"/>
            </geometry>
            <material name="roller_16_parts_material">
                <color rgba="0.752941 0.752941 0.752941 1.0"/>
            </material>
        </visual>
    </link>
    <!-- Joint from back_left_wheel to roller_16 -->
    <joint name="blw_r4" type="revolute">
        <origin xyz="0.0806217 -0.0299257 0.039" rpy="2.78255 0.714734 -2.44634"/>
        <parent link="back_left_wheel"/>
        <child link="roller_16"/>
        <axis xyz="0 0 1"/>
        <limit effort="10" velocity="10" lower="-3.141592653589793" upper="3.141592653589793"/>
    </joint>
    <!-- Link roller_17 -->
    <link name="roller_17">
        <inertial>
            <origin xyz="1.42681e-16 -1.5644e-16 -4.11978e-16" rpy="0 0 0"/>
            <mass value="0.0493467"/>
            <inertia ixx="1.86522e-05" ixy="1.8618e-21" ixz="-9.15534e-22" iyy="1.86522e-05" iyz="-1.98557e-21" izz="5.80503e-06"/>
        </inertial>
        <!-- Part roller_17_parts -->
        <collision>
            <origin xyz="-3.10992e-17 -1.67934e-17 -1.78688e-16" rpy="-1.86811e-16 -9.72329e-17 2.74345e-17"/>
            <geometry>
                <sphere radius="0.0155"/>
            </geometry>
        </collision>
        <collision>
            <origin xyz="-5.8758e-17 -1.93474e-17 0.0085" rpy="-1.86811e-16 -9.72329e-17 2.74345e-17"/>
            <geometry>
                <sphere radius="0.0155"/>
            </geometry>
        </collision>
        <collision>
            <origin xyz="-3.37231e-18 -1.45712e-17 -0.0085" rpy="-1.86811e-16 -9.72329e-17 2.74345e-17"/>
            <geometry>
                <sphere radius="0.0155"/>
            </geometry>
        </collision>
        <collision>
            <origin xyz="-1.49925e-17 -7.37366e-18 0.0165" rpy="-1.86811e-16 -9.72329e-17 2.74345e-17"/>
            <geometry>
                <sphere radius="0.015"/>
            </geometry>
        </collision>
        <collision>
            <origin xyz="-4.73057e-17 -2.53959e-17 -0.0165" rpy="-1.86811e-16 -9.72329e-17 2.74345e-17"/>
            <geometry>
                <sphere radius="0.015"/>
            </geometry>
        </collision>
        <collision>
            <origin xyz="-2.43864e-17 -1.32007e-18 0.0235" rpy="-1.86811e-16 -9.72329e-17 2.74345e-17"/>
            <geometry>
                <sphere radius="0.014"/>
            </geometry>
        </collision>
        <collision>
            <origin xyz="-3.70444e-17 -3.14495e-17 -0.0235" rpy="-1.86811e-16 -9.72329e-17 2.74345e-17"/>
            <geometry>
                <sphere radius="0.014"/>
            </geometry>
        </collision>
        <visual>
            <origin xyz="1.66533e-16 -1.52656e-16 -4.12864e-16" rpy="-1.00301 0.575895 0.479378"/>
            <geometry>
                <mesh filename="package://assets/merged/roller_17_visual.stl"/>
            </geometry>
            <material name="roller_17_parts_material">
                <color rgba="0.752941 0.752941 0.752941 1.0"/>
            </material>
        </visual>
    </link>
    <!-- Joint from back_left_wheel to roller_17 -->
    <joint name="blw_r5" type="revolute">
        <origin xyz="0.0548539 -0.0662269 0.039" rpy="2.78255 0.714734 -2.96994"/>
        <parent link="back_left_wheel"/>
        <child link="roller_17"/>
        <axis xyz="0 0 1"/>
        <limit effort="10" velocity="10" lower="-3.141592653589793" upper="3.141592653589793"/>
    </joint>
    <!-- Link roller_18 -->
    <link name="roller_18">
        <inertial>
            <origin xyz="1.74199e-16 -1.92513e-16 -3.69091e-16" rpy="0 0 0"/>
            <mass value="0.0493467"/>
            <inertia ixx="1.86522e-05" ixy="1.33715e-21" ixz="5.13039e-22" iyy="1.86522e-05" iyz="-7.81496e-22" izz="5.80503e-06"/>
        </inertial>
        <!-- Part roller_18_parts -->
        <collision>
            <origin xyz="4.18818e-19 -5.2866e-17 -1.35801e-16" rpy="-7.48234e-17 -5.58727e-17 3.10149e-17"/>
            <geometry>
                <sphere radius="0.0155"/>
            </geometry>
        </collision>
        <collision>
            <origin xyz="-7.01952e-18 -7.26404e-17 0.0085" rpy="-7.48234e-17 -5.58727e-17 3.10149e-17"/>
            <geometry>
                <sphere radius="0.0155"/>
            </geometry>
        </collision>
        <collision>
            <origin xyz="7.8484e-18 -3.28362e-17 -0.0085" rpy="-7.48234e-17 -5.58727e-17 3.10149e-17"/>
            <geometry>
                <sphere radius="0.0155"/>
            </geometry>
        </collision>
        <collision>
            <origin xyz="6.57096e-18 -1.82137e-17 0.0165" rpy="-7.48234e-17 -5.58727e-17 3.10149e-17"/>
            <geometry>
                <sphere radius="0.015"/>
            </geometry>
        </collision>
        <collision>
            <origin xyz="-5.74208e-18 -8.73713e-17 -0.0165" rpy="-7.48234e-17 -5.58727e-17 3.10149e-17"/>
            <geometry>
                <sphere radius="0.015"/>
            </geometry>
        </collision>
        <collision>
            <origin xyz="4.38586e-18 -4.38236e-17 0.0235" rpy="-7.48234e-17 -5.58727e-17 3.10149e-17"/>
            <geometry>
                <sphere radius="0.014"/>
            </geometry>
        </collision>
        <collision>
            <origin xyz="-3.34013e-18 -6.17615e-17 -0.0235" rpy="-7.48234e-17 -5.58727e-17 3.10149e-17"/>
            <geometry>
                <sphere radius="0.014"/>
            </geometry>
        </collision>
        <visual>
            <origin xyz="1.66533e-16 -2.22045e-16 -3.87277e-16" rpy="-1.40502 0.771399 -1.71998"/>
            <geometry>
                <mesh filename="package://assets/merged/roller_18_visual.stl"/>
            </geometry>
            <material name="roller_18_parts_material">
                <color rgba="0.752941 0.752941 0.752941 1.0"/>
            </material>
        </visual>
    </link>
    <!-- Joint from back_left_wheel to roller_18 -->
    <joint name="blw_r6" type="revolute">
        <origin xyz="0.0143878 -0.0847808 0.039" rpy="2.39411 -0.268603 1.46005"/>
        <parent link="back_left_wheel"/>
        <child link="roller_18"/>
        <axis xyz="0 0 1"/>
        <limit effort="10" velocity="10" lower="-3.141592653589793" upper="3.141592653589793"/>
    </joint>
    <!-- Link roller_19 -->
    <link name="roller_19">
        <inertial>
            <origin xyz="1.60247e-16 -8.33311e-17 -4.11764e-16" rpy="0 0 0"/>
            <mass value="0.0493467"/>
            <inertia ixx="1.86522e-05" ixy="-9.04653e-22" ixz="2.3156e-21" iyy="1.86522e-05" iyz="-1.85981e-21" izz="5.80503e-06"/>
        </inertial>
        <!-- Part roller_19_parts -->
        <collision>
            <origin xyz="-1.35332e-17 5.63156e-17 -1.78474e-16" rpy="-1.72951e-16 -1.19516e-16 -1.14202e-17"/>
            <geometry>
                <sphere radius="0.0155"/>
            </geometry>
        </collision>
        <collision>
            <origin xyz="-1.34732e-17 5.51812e-17 0.0085" rpy="-1.72951e-16 -1.19516e-16 -1.14202e-17"/>
            <geometry>
                <sphere radius="0.0155"/>
            </geometry>
        </collision>
        <collision>
            <origin xyz="-1.24918e-17 5.89573e-17 -0.0085" rpy="-1.72951e-16 -1.19516e-16 -1.14202e-17"/>
            <geometry>
                <sphere radius="0.0155"/>
            </geometry>
        </collision>
        <collision>
            <origin xyz="-2.53152e-17 6.25705e-17 0.0165" rpy="-1.72951e-16 -1.19516e-16 -1.14202e-17"/>
            <geometry>
                <sphere radius="0.015"/>
            </geometry>
        </collision>
        <collision>
            <origin xyz="-1.43901e-18 5.02209e-17 -0.0165" rpy="-1.72951e-16 -1.19516e-16 -1.14202e-17"/>
            <geometry>
                <sphere radius="0.015"/>
            </geometry>
        </collision>
        <collision>
            <origin xyz="-2.70739e-17 6.33745e-17 0.0235" rpy="-1.72951e-16 -1.19516e-16 -1.14202e-17"/>
            <geometry>
                <sphere radius="0.014"/>
            </geometry>
        </collision>
        <collision>
            <origin xyz="-1.1399e-19 4.94169e-17 -0.0235" rpy="-1.72951e-16 -1.19516e-16 -1.14202e-17"/>
            <geometry>
                <sphere radius="0.014"/>
            </geometry>
        </collision>
        <visual>
            <origin xyz="1.66533e-16 -8.32667e-17 -4.30211e-16" rpy="-1.90574 0.724678 2.27337"/>
            <geometry>
                <mesh filename="package://assets/merged/roller_19_visual.stl"/>
            </geometry>
            <material name="roller_19_parts_material">
                <color rgba="0.752941 0.752941 0.752941 1.0"/>
            </material>
        </visual>
    </link>
    <!-- Joint from back_left_wheel to roller_19 -->
    <joint name="blw_r7" type="revolute">
        <origin xyz="-0.0299338 -0.0806159 0.039" rpy="-2.78255 -0.714734 -0.875544"/>
        <parent link="back_left_wheel"/>
        <child link="roller_19"/>
        <axis xyz="0 0 1"/>
        <limit effort="10" velocity="10" lower="-3.141592653589793" upper="3.141592653589793"/>
    </joint>
    <!-- Link roller_20 -->
    <link name="roller_20">
        <inertial>
            <origin xyz="1.94726e-16 -1.31869e-16 -4.25082e-16" rpy="0 0 0"/>
            <mass value="0.0493467"/>
            <inertia ixx="1.86522e-05" ixy="7.1671e-22" ixz="3.45513e-22" iyy="1.86522e-05" iyz="-3.93821e-21" izz="5.80503e-06"/>
        </inertial>
        <!-- Part roller_20_parts -->
        <collision>
            <origin xyz="2.09457e-17 7.77748e-18 -1.91792e-16" rpy="-1.41096e-16 -5.66999e-17 5.84398e-17"/>
            <geometry>
                <sphere radius="0.0155"/>
            </geometry>
        </collision>
        <collision>
            <origin xyz="2.24023e-17 2.84383e-18 0.0085" rpy="-1.41096e-16 -5.66999e-17 5.84398e-17"/>
            <geometry>
                <sphere radius="0.0155"/>
            </geometry>
        </collision>
        <collision>
            <origin xyz="1.93719e-17 1.29664e-17 -0.0085" rpy="-1.41096e-16 -5.66999e-17 5.84398e-17"/>
            <geometry>
                <sphere radius="0.0155"/>
            </geometry>
        </collision>
        <collision>
            <origin xyz="7.65748e-18 1.91695e-17 0.0165" rpy="-1.41096e-16 -5.66999e-17 5.84398e-17"/>
            <geometry>
                <sphere radius="0.015"/>
            </geometry>
        </collision>
        <collision>
            <origin xyz="3.72609e-17 1.56143e-17 -0.0165" rpy="-1.41096e-16 -5.66999e-17 5.84398e-17"/>
            <geometry>
                <sphere radius="0.015"/>
            </geometry>
        </collision>
        <collision>
            <origin xyz="4.7284e-18 8.45125e-18 0.0235" rpy="-1.41096e-16 -5.66999e-17 5.84398e-17"/>
            <geometry>
                <sphere radius="0.014"/>
            </geometry>
        </collision>
        <collision>
            <origin xyz="4.04069e-17 2.6441e-17 -0.0235" rpy="-1.41096e-16 -5.66999e-17 5.84398e-17"/>
            <geometry>
                <sphere radius="0.014"/>
            </geometry>
        </collision>
        <visual>
            <origin xyz="1.80411e-16 -1.59595e-16 -4.44089e-16" rpy="-1.73657 -0.771399 1.42161"/>
            <geometry>
                <mesh filename="package://assets/merged/roller_20_visual.stl"/>
            </geometry>
            <material name="roller_20_parts_material">
                <color rgba="0.752941 0.752941 0.752941 1.0"/>
            </material>
        </visual>
    </link>
    <!-- Joint from back_left_wheel to roller_20 -->
    <joint name="blw_r8" type="revolute">
        <origin xyz="-0.0143902 0.0847946 0.039" rpy="2.39411 -0.268603 -1.68155"/>
        <parent link="back_left_wheel"/>
        <child link="roller_20"/>
        <axis xyz="0 0 1"/>
        <limit effort="10" velocity="10" lower="-3.141592653589793" upper="3.141592653589793"/>
    </joint>
    <!-- Link roller_21 -->
    <link name="roller_21">
        <inertial>
            <origin xyz="1.40478e-16 -1.30604e-16 -3.89614e-16" rpy="0 0 0"/>
            <mass value="0.0493467"/>
            <inertia ixx="1.86522e-05" ixy="6.34214e-23" ixz="-1.05867e-21" iyy="1.86522e-05" iyz="-3.40588e-21" izz="5.80503e-06"/>
        </inertial>
        <!-- Part roller_21_parts -->
        <collision>
            <origin xyz="-3.33025e-17 9.04264e-18 -1.56324e-16" rpy="-2.541e-16 -3.86598e-17 -3.50847e-17"/>
            <geometry>
                <sphere radius="0.0155"/>
            </geometry>
        </collision>
        <collision>
            <origin xyz="-4.1949e-17 -4.97713e-19 0.0085" rpy="-2.541e-16 -3.86598e-17 -3.50847e-17"/>
            <geometry>
                <sphere radius="0.0155"/>
            </geometry>
        </collision>
        <collision>
            <origin xyz="-2.44222e-17 1.85982e-17 -0.0085" rpy="-2.541e-16 -3.86598e-17 -3.50847e-17"/>
            <geometry>
                <sphere radius="0.0155"/>
            </geometry>
        </collision>
        <collision>
            <origin xyz="-2.96965e-17 2.58937e-17 0.0165" rpy="-2.541e-16 -3.86598e-17 -3.50847e-17"/>
            <geometry>
                <sphere radius="0.015"/>
            </geometry>
        </collision>
        <collision>
            <origin xyz="-3.7542e-17 -7.79318e-18 -0.0165" rpy="-2.541e-16 -3.86598e-17 -3.50847e-17"/>
            <geometry>
                <sphere radius="0.015"/>
            </geometry>
        </collision>
        <collision>
            <origin xyz="-2.97351e-17 1.22185e-17 0.0235" rpy="-2.541e-16 -3.86598e-17 -3.50847e-17"/>
            <geometry>
                <sphere radius="0.014"/>
            </geometry>
        </collision>
        <collision>
            <origin xyz="-2.438e-17 7.56393e-18 -0.0235" rpy="-2.541e-16 -3.86598e-17 -3.50847e-17"/>
            <geometry>
                <sphere radius="0.014"/>
            </geometry>
        </collision>
        <visual>
            <origin xyz="1.38778e-16 -1.41814e-16 -3.88578e-16" rpy="-2.13858 -0.575895 2.05017"/>
            <geometry>
                <mesh filename="package://assets/merged/roller_21_visual.stl"/>
            </geometry>
            <material name="roller_21_parts_material">
                <color rgba="0.752941 0.752941 0.752941 1.0"/>
            </material>
        </visual>
    </link>
    <!-- Joint from back_left_wheel to roller_21 -->
    <joint name="blw_r9" type="revolute">
        <origin xyz="-0.0548563 0.0662407 0.039" rpy="2.39411 -0.268603 -1.15795"/>
        <parent link="back_left_wheel"/>
        <child link="roller_21"/>
        <axis xyz="0 0 1"/>
        <limit effort="10" velocity="10" lower="-3.141592653589793" upper="3.141592653589793"/>
    </joint>
    <!-- Link roller_22 -->
    <link name="roller_22">
        <inertial>
            <origin xyz="1.46849e-16 -1.36954e-16 -4.3857e-16" rpy="0 0 0"/>
            <mass value="0.0493467"/>
            <inertia ixx="1.86522e-05" ixy="-3.59541e-21" ixz="5.10311e-22" iyy="1.86522e-05" iyz="-7.33178e-22" izz="5.80503e-06"/>
        </inertial>
        <!-- Part roller_22_parts -->
        <collision>
            <origin xyz="-2.69311e-17 2.69272e-18 -2.0528e-16" rpy="-1.27281e-16 1.45587e-17 -6.70717e-17"/>
            <geometry>
                <sphere radius="0.0155"/>
            </geometry>
        </collision>
        <collision>
            <origin xyz="-3.76352e-17 -1.55675e-18 0.0085" rpy="-1.27281e-16 1.45587e-17 -6.70717e-17"/>
            <geometry>
                <sphere radius="0.0155"/>
            </geometry>
        </collision>
        <collision>
            <origin xyz="-1.58389e-17 7.03737e-18 -0.0085" rpy="-1.27281e-16 1.45587e-17 -6.70717e-17"/>
            <geometry>
                <sphere radius="0.0155"/>
            </geometry>
        </collision>
        <collision>
            <origin xyz="-3.17187e-17 2.9256e-17 0.0165" rpy="-1.27281e-16 1.45587e-17 -6.70717e-17"/>
            <geometry>
                <sphere radius="0.015"/>
            </geometry>
        </collision>
        <collision>
            <origin xyz="-2.21891e-17 -2.42091e-17 -0.0165" rpy="-1.27281e-16 1.45587e-17 -6.70717e-17"/>
            <geometry>
                <sphere radius="0.015"/>
            </geometry>
        </collision>
        <collision>
            <origin xyz="-2.30877e-17 -1.75956e-18 0.0235" rpy="-1.27281e-16 1.45587e-17 -6.70717e-17"/>
            <geometry>
                <sphere radius="0.014"/>
            </geometry>
        </collision>
        <collision>
            <origin xyz="-3.16874e-17 6.8065e-18 -0.0235" rpy="-1.27281e-16 1.45587e-17 -6.70717e-17"/>
            <geometry>
                <sphere radius="0.014"/>
            </geometry>
        </collision>
        <visual>
            <origin xyz="1.38778e-16 -1.52656e-16 -4.44089e-16" rpy="-2.32393 -0.248666 2.50013"/>
            <geometry>
                <mesh filename="package://assets/merged/roller_22_visual.stl"/>
            </geometry>
            <material name="roller_22_parts_material">
                <color rgba="0.752941 0.752941 0.752941 1.0"/>
            </material>
        </visual>
    </link>
    <!-- Joint from back_left_wheel to roller_22 -->
    <joint name="blw_r10" type="revolute">
        <origin xyz="-0.080624 0.0299395 0.039" rpy="2.39411 -0.268603 -0.634348"/>
        <parent link="back_left_wheel"/>
        <child link="roller_22"/>
        <axis xyz="0 0 1"/>
        <limit effort="10" velocity="10" lower="-3.141592653589793" upper="3.141592653589793"/>
    </joint>
    <!-- Link roller_23 -->
    <link name="roller_23">
        <inertial>
            <origin xyz="1.51228e-16 -1.66815e-16 -4.06165e-16" rpy="0 0 0"/>
            <mass value="0.0493467"/>
            <inertia ixx="1.86522e-05" ixy="-5.62813e-22" ixz="3.36341e-21" iyy="1.86522e-05" iyz="-2.32893e-21" izz="5.80503e-06"/>
        </inertial>
        <!-- Part roller_23_parts -->
        <collision>
            <origin xyz="-2.25529e-17 -2.71681e-17 -1.72875e-16" rpy="-2.06971e-16 -1.80437e-16 3.34018e-17"/>
            <geometry>
                <sphere radius="0.0155"/>
            </geometry>
        </collision>
        <collision>
            <origin xyz="-1.13217e-17 -3.942e-17 0.0085" rpy="-2.06971e-16 -1.80437e-16 3.34018e-17"/>
            <geometry>
                <sphere radius="0.0155"/>
            </geometry>
        </collision>
        <collision>
            <origin xyz="-3.37545e-17 -1.48898e-17 -0.0085" rpy="-2.06971e-16 -1.80437e-16 3.34018e-17"/>
            <geometry>
                <sphere radius="0.0155"/>
            </geometry>
        </collision>
        <collision>
            <origin xyz="-3.30425e-17 -1.70444e-17 0.0165" rpy="-2.06971e-16 -1.80437e-16 3.34018e-17"/>
            <geometry>
                <sphere radius="0.015"/>
            </geometry>
        </collision>
        <collision>
            <origin xyz="-1.20337e-17 -3.74822e-17 -0.0165" rpy="-2.06971e-16 -1.80437e-16 3.34018e-17"/>
            <geometry>
                <sphere radius="0.015"/>
            </geometry>
        </collision>
        <collision>
            <origin xyz="-3.15974e-17 -2.09448e-17 0.0235" rpy="-2.06971e-16 -1.80437e-16 3.34018e-17"/>
            <geometry>
                <sphere radius="0.014"/>
            </geometry>
        </collision>
        <collision>
            <origin xyz="-1.83983e-17 -3.28424e-17 -0.0235" rpy="-2.06971e-16 -1.80437e-16 3.34018e-17"/>
            <geometry>
                <sphere radius="0.014"/>
            </geometry>
        </collision>
        <visual>
            <origin xyz="1.66533e-16 -1.66533e-16 -4.16334e-16" rpy="-2.3491 0.118587 1.30549"/>
            <geometry>
                <mesh filename="package://assets/merged/roller_23_visual.stl"/>
            </geometry>
            <material name="roller_23_parts_material">
                <color rgba="0.752941 0.752941 0.752941 1.0"/>
            </material>
        </visual>
    </link>
    <!-- Joint from back_left_wheel to roller_23 -->
    <joint name="blw_r11" type="revolute">
        <origin xyz="-0.0847889 -0.0143821 0.039" rpy="-2.78255 -0.714734 -1.92274"/>
        <parent link="back_left_wheel"/>
        <child link="roller_23"/>
        <axis xyz="0 0 1"/>
        <limit effort="10" velocity="10" lower="-3.141592653589793" upper="3.141592653589793"/>
    </joint>
    <!-- Link roller_24 -->
    <link name="roller_24">
        <inertial>
            <origin xyz="1.84919e-16 -6.21236e-17 -4.12165e-16" rpy="0 0 0"/>
            <mass value="0.0493467"/>
            <inertia ixx="1.86522e-05" ixy="8.36673e-22" ixz="1.61307e-21" iyy="1.86522e-05" iyz="-2.37073e-21" izz="5.80503e-06"/>
        </inertial>
        <!-- Part roller_24_parts -->
        <collision>
            <origin xyz="1.11385e-17 7.75231e-17 -1.78875e-16" rpy="-2.5537e-16 -6.86316e-17 -1.4294e-17"/>
            <geometry>
                <sphere radius="0.0155"/>
            </geometry>
        </collision>
        <collision>
            <origin xyz="1.38561e-17 6.95402e-17 0.0085" rpy="-2.5537e-16 -6.86316e-17 -1.4294e-17"/>
            <geometry>
                <sphere radius="0.0155"/>
            </geometry>
        </collision>
        <collision>
            <origin xyz="7.87653e-18 8.50959e-17 -0.0085" rpy="-2.5537e-16 -6.86316e-17 -1.4294e-17"/>
            <geometry>
                <sphere radius="0.0155"/>
            </geometry>
        </collision>
        <collision>
            <origin xyz="8.85958e-18 9.14567e-17 0.0165" rpy="-2.5537e-16 -6.86316e-17 -1.4294e-17"/>
            <geometry>
                <sphere radius="0.015"/>
            </geometry>
        </collision>
        <collision>
            <origin xyz="1.17939e-17 6.2627e-17 -0.0165" rpy="-2.5537e-16 -6.86316e-17 -1.4294e-17"/>
            <geometry>
                <sphere radius="0.015"/>
            </geometry>
        </collision>
        <collision>
            <origin xyz="6.08496e-18 7.6092e-17 0.0235" rpy="-2.5537e-16 -6.86316e-17 -1.4294e-17"/>
            <geometry>
                <sphere radius="0.014"/>
            </geometry>
        </collision>
        <collision>
            <origin xyz="1.58594e-17 7.86627e-17 -0.0235" rpy="-2.5537e-16 -6.86316e-17 -1.4294e-17"/>
            <geometry>
                <sphere radius="0.014"/>
            </geometry>
        </collision>
        <visual>
            <origin xyz="1.94289e-16 -5.55112e-17 -4.30211e-16" rpy="-2.22708 0.467917 1.71585"/>
            <geometry>
                <mesh filename="package://assets/merged/roller_24_visual.stl"/>
            </geometry>
            <material name="roller_24_parts_material">
                <color rgba="0.752941 0.752941 0.752941 1.0"/>
            </material>
        </visual>
    </link>
    <!-- Joint from back_left_wheel to roller_24 -->
    <joint name="blw_r12" type="revolute">
        <origin xyz="-0.066235 -0.0548482 0.039" rpy="-2.78255 -0.714734 -1.39914"/>
        <parent link="back_left_wheel"/>
        <child link="roller_24"/>
        <axis xyz="0 0 1"/>
        <limit effort="10" velocity="10" lower="-3.141592653589793" upper="3.141592653589793"/>
    </joint>
    <!-- Joint from base_link to back_left_wheel -->
    <joint name="back_left_wheel" type="continuous">
        <origin xyz="-0.2735 0.24 0.065" rpy="1.5708 7.65429e-15 -3.14159"/>
        <parent link="base_link"/>
        <child link="back_left_wheel"/>
        <axis xyz="0 0 1"/>
        <limit effort="10" velocity="10"/>
    </joint>
    <!-- Link front_left_wheel -->
    <link name="front_left_wheel">
        <inertial>
            <origin xyz="3.47124e-06 -2.04529e-05 0.039002" rpy="0 0 0"/>
            <mass value="0.942157"/>
            <inertia ixx="0.00202095" ixy="-9.22565e-07" ixz="7.0304e-12" iyy="0.00202623" iyz="-7.62497e-11" izz="0.00255146"/>
        </inertial>
        <!-- Part front_left_wheel_parts -->
        <visual>
            <origin xyz="3.47124e-06 -2.04529e-05 0.039002" rpy="1.5708 3.62788e-15 3.14159"/>
            <geometry>
                <mesh filename="package://assets/merged/front_left_wheel_visual.stl"/>
            </geometry>
            <material name="front_left_wheel_parts_material">
                <color rgba="0.792157 0.819608 0.933333 1.0"/>
            </material>
        </visual>
    </link>
    <!-- Link roller_25 -->
    <link name="roller_25">
        <inertial>
            <origin xyz="1.7244e-16 -1.70218e-16 -3.59727e-16" rpy="0 0 0"/>
            <mass value="0.0493467"/>
            <inertia ixx="1.86522e-05" ixy="1.35152e-21" ixz="2.97384e-21" iyy="1.86522e-05" iyz="-2.62295e-21" izz="5.80503e-06"/>
        </inertial>
        <!-- Part roller_25_parts -->
        <collision>
            <origin xyz="-1.34024e-18 -3.05715e-17 -1.26437e-16" rpy="-2.24276e-16 -2.06216e-16 -3.61915e-18"/>
            <geometry>
                <sphere radius="0.0155"/>
            </geometry>
        </collision>
        <collision>
            <origin xyz="6.8174e-18 -2.47864e-17 0.0085" rpy="-2.24276e-16 -2.06216e-16 -3.61915e-18"/>
            <geometry>
                <sphere radius="0.0155"/>
            </geometry>
        </collision>
        <collision>
            <origin xyz="-9.72135e-18 -3.6312e-17 -0.0085" rpy="-2.24276e-16 -2.06216e-16 -3.61915e-18"/>
            <geometry>
                <sphere radius="0.0155"/>
            </geometry>
        </collision>
        <collision>
            <origin xyz="1.11331e-17 -2.77321e-17 0.0165" rpy="-2.24276e-16 -2.06216e-16 -3.61915e-18"/>
            <geometry>
                <sphere radius="0.015"/>
            </geometry>
        </collision>
        <collision>
            <origin xyz="-1.40371e-17 -3.35831e-17 -0.0165" rpy="-2.24276e-16 -2.06216e-16 -3.61915e-18"/>
            <geometry>
                <sphere radius="0.015"/>
            </geometry>
        </collision>
        <collision>
            <origin xyz="1.53478e-17 -3.02053e-17 0.0235" rpy="-2.24276e-16 -2.06216e-16 -3.61915e-18"/>
            <geometry>
                <sphere radius="0.014"/>
            </geometry>
        </collision>
        <collision>
            <origin xyz="-1.82517e-17 -3.11099e-17 -0.0235" rpy="-2.24276e-16 -2.06216e-16 -3.61915e-18"/>
            <geometry>
                <sphere radius="0.014"/>
            </geometry>
        </collision>
        <visual>
            <origin xyz="1.66533e-16 -1.66533e-16 -3.33067e-16" rpy="-1.40502 0.771399 -0.149186"/>
            <geometry>
                <mesh filename="package://assets/merged/roller_25_visual.stl"/>
            </geometry>
            <material name="roller_25_parts_material">
                <color rgba="0.752941 0.752941 0.752941 1.0"/>
            </material>
        </visual>
    </link>
    <!-- Joint from front_left_wheel to roller_25 -->
    <joint name="flw_r1" type="revolute">
        <origin xyz="-0.014389 0.0847877 0.039" rpy="2.78255 0.714734 2.78965"/>
        <parent link="front_left_wheel"/>
        <child link="roller_25"/>
        <axis xyz="0 0 1"/>
        <limit effort="10" velocity="10" lower="-3.141592653589793" upper="3.141592653589793"/>
    </joint>
    <!-- Link roller_26 -->
    <link name="roller_26">
        <inertial>
            <origin xyz="1.64619e-16 -1.88559e-16 -3.72693e-16" rpy="0 0 0"/>
            <mass value="0.0493467"/>
            <inertia ixx="1.86522e-05" ixy="-2.30645e-21" ixz="3.23936e-21" iyy="1.86522e-05" iyz="-2.0948e-21" izz="5.80503e-06"/>
        </inertial>
        <!-- Part roller_26_parts -->
        <collision>
            <origin xyz="-9.16136e-18 -4.89118e-17 -1.39402e-16" rpy="-2.28418e-16 -1.10896e-16 -5.35143e-18"/>
            <geometry>
                <sphere radius="0.0155"/>
            </geometry>
        </collision>
        <collision>
            <origin xyz="-7.22691e-18 -3.85318e-17 0.0085" rpy="-2.28418e-16 -1.10896e-16 -5.35143e-18"/>
            <geometry>
                <sphere radius="0.0155"/>
            </geometry>
        </collision>
        <collision>
            <origin xyz="-1.12172e-17 -5.91316e-17 -0.0085" rpy="-2.28418e-16 -1.10896e-16 -5.35143e-18"/>
            <geometry>
                <sphere radius="0.0155"/>
            </geometry>
        </collision>
        <collision>
            <origin xyz="-1.00724e-17 -5.38207e-17 0.0165" rpy="-2.28418e-16 -1.10896e-16 -5.35143e-18"/>
            <geometry>
                <sphere radius="0.015"/>
            </geometry>
        </collision>
        <collision>
            <origin xyz="-8.37175e-18 -4.38427e-17 -0.0165" rpy="-2.28418e-16 -1.10896e-16 -5.35143e-18"/>
            <geometry>
                <sphere radius="0.015"/>
            </geometry>
        </collision>
        <collision>
            <origin xyz="-4.93284e-18 -5.78796e-17 0.0235" rpy="-2.28418e-16 -1.10896e-16 -5.35143e-18"/>
            <geometry>
                <sphere radius="0.014"/>
            </geometry>
        </collision>
        <collision>
            <origin xyz="-6.71601e-20 -5.53963e-17 -0.0235" rpy="-2.28418e-16 -1.10896e-16 -5.35143e-18"/>
            <geometry>
                <sphere radius="0.014"/>
            </geometry>
        </collision>
        <visual>
            <origin xyz="1.76942e-16 -1.80411e-16 -3.88578e-16" rpy="-1.90574 0.724678 2.27337"/>
            <geometry>
                <mesh filename="package://assets/merged/roller_26_visual.stl"/>
            </geometry>
            <material name="roller_26_parts_material">
                <color rgba="0.752941 0.752941 0.752941 1.0"/>
            </material>
        </visual>
    </link>
    <!-- Joint from front_left_wheel to roller_26 -->
    <joint name="flw_r2" type="revolute">
        <origin xyz="0.0299326 0.0806228 0.039" rpy="-2.78255 -0.714734 -0.875544"/>
        <parent link="front_left_wheel"/>
        <child link="roller_26"/>
        <axis xyz="0 0 1"/>
        <limit effort="10" velocity="10" lower="-3.141592653589793" upper="3.141592653589793"/>
    </joint>
    <!-- Link roller_27 -->
    <link name="roller_27">
        <inertial>
            <origin xyz="1.59745e-16 -1.3017e-16 -4.24154e-16" rpy="0 0 0"/>
            <mass value="0.0493467"/>
            <inertia ixx="1.86522e-05" ixy="3.25661e-22" ixz="2.60632e-21" iyy="1.86522e-05" iyz="-4.87466e-21" izz="5.80503e-06"/>
        </inertial>
        <!-- Part roller_27_parts -->
        <collision>
            <origin xyz="-1.40353e-17 9.47626e-18 -1.90863e-16" rpy="-3.80446e-16 -1.20206e-16 2.35687e-17"/>
            <geometry>
                <sphere radius="0.0155"/>
            </geometry>
        </collision>
        <collision>
            <origin xyz="-3.5959e-19 8.59552e-18 0.0085" rpy="-3.80446e-16 -1.20206e-16 2.35687e-17"/>
            <geometry>
                <sphere radius="0.0155"/>
            </geometry>
        </collision>
        <collision>
            <origin xyz="-2.76098e-17 1.02824e-17 -0.0085" rpy="-3.80446e-16 -1.20206e-16 2.35687e-17"/>
            <geometry>
                <sphere radius="0.0155"/>
            </geometry>
        </collision>
        <collision>
            <origin xyz="-1.66354e-17 2.29144e-17 0.0165" rpy="-3.80446e-16 -1.20206e-16 2.35687e-17"/>
            <geometry>
                <sphere radius="0.015"/>
            </geometry>
        </collision>
        <collision>
            <origin xyz="-1.17677e-17 -4.25332e-18 -0.0165" rpy="-3.80446e-16 -1.20206e-16 2.35687e-17"/>
            <geometry>
                <sphere radius="0.015"/>
            </geometry>
        </collision>
        <collision>
            <origin xyz="-2.34565e-18 1.28025e-17 0.0235" rpy="-3.80446e-16 -1.20206e-16 2.35687e-17"/>
            <geometry>
                <sphere radius="0.014"/>
            </geometry>
        </collision>
        <collision>
            <origin xyz="-1.573e-17 1.03596e-17 -0.0235" rpy="-3.80446e-16 -1.20206e-16 2.35687e-17"/>
            <geometry>
                <sphere radius="0.014"/>
            </geometry>
        </collision>
        <visual>
            <origin xyz="1.66533e-16 -1.249e-16 -4.44089e-16" rpy="-2.22708 0.467917 1.71585"/>
            <geometry>
                <mesh filename="package://assets/merged/roller_27_visual.stl"/>
            </geometry>
            <material name="roller_27_parts_material">
                <color rgba="0.752941 0.752941 0.752941 1.0"/>
            </material>
        </visual>
    </link>
    <!-- Joint from front_left_wheel to roller_27 -->
    <joint name="flw_r3" type="revolute">
        <origin xyz="0.0662338 0.0548551 0.039" rpy="-2.78255 -0.714734 -1.39914"/>
        <parent link="front_left_wheel"/>
        <child link="roller_27"/>
        <axis xyz="0 0 1"/>
        <limit effort="10" velocity="10" lower="-3.141592653589793" upper="3.141592653589793"/>
    </joint>
    <!-- Link roller_28 -->
    <link name="roller_28">
        <inertial>
            <origin xyz="1.3823e-16 -1.82911e-16 -4.19409e-16" rpy="0 0 0"/>
            <mass value="0.0493467"/>
            <inertia ixx="1.86522e-05" ixy="1.07076e-22" ixz="1.91853e-21" iyy="1.86522e-05" iyz="-2.70751e-21" izz="5.80503e-06"/>
        </inertial>
        <!-- Part roller_28_parts -->
        <collision>
            <origin xyz="-3.555e-17 -4.32641e-17 -1.86119e-16" rpy="-2.41731e-16 -1.55359e-16 -5.24783e-17"/>
            <geometry>
                <sphere radius="0.0155"/>
            </geometry>
        </collision>
        <collision>
            <origin xyz="-4.11948e-17 -2.5353e-17 0.0085" rpy="-2.41731e-16 -1.55359e-16 -5.24783e-17"/>
            <geometry>
                <sphere radius="0.0155"/>
            </geometry>
        </collision>
        <collision>
            <origin xyz="-2.98757e-17 -6.11487e-17 -0.0085" rpy="-2.41731e-16 -1.55359e-16 -5.24783e-17"/>
            <geometry>
                <sphere radius="0.0155"/>
            </geometry>
        </collision>
        <collision>
            <origin xyz="-2.22926e-17 -3.24391e-17 0.0165" rpy="-2.41731e-16 -1.55359e-16 -5.24783e-17"/>
            <geometry>
                <sphere radius="0.015"/>
            </geometry>
        </collision>
        <collision>
            <origin xyz="-4.87779e-17 -5.40627e-17 -0.0165" rpy="-2.41731e-16 -1.55359e-16 -5.24783e-17"/>
            <geometry>
                <sphere radius="0.015"/>
            </geometry>
        </collision>
        <collision>
            <origin xyz="-4.30091e-17 -4.79981e-17 0.0235" rpy="-2.41731e-16 -1.55359e-16 -5.24783e-17"/>
            <geometry>
                <sphere radius="0.014"/>
            </geometry>
        </collision>
        <collision>
            <origin xyz="-2.80613e-17 -3.87205e-17 -0.0235" rpy="-2.41731e-16 -1.55359e-16 -5.24783e-17"/>
            <geometry>
                <sphere radius="0.014"/>
            </geometry>
        </collision>
        <visual>
            <origin xyz="1.38778e-16 -1.80411e-16 -4.44089e-16" rpy="-2.3491 0.118587 1.30549"/>
            <geometry>
                <mesh filename="package://assets/merged/roller_28_visual.stl"/>
            </geometry>
            <material name="roller_28_parts_material">
                <color rgba="0.752941 0.752941 0.752941 1.0"/>
            </material>
        </visual>
    </link>
    <!-- Joint from front_left_wheel to roller_28 -->
    <joint name="flw_r4" type="revolute">
        <origin xyz="0.0847877 0.014389 0.039" rpy="-2.78255 -0.714734 -1.92274"/>
        <parent link="front_left_wheel"/>
        <child link="roller_28"/>
        <axis xyz="0 0 1"/>
        <limit effort="10" velocity="10" lower="-3.141592653589793" upper="3.141592653589793"/>
    </joint>
    <!-- Link roller_29 -->
    <link name="roller_29">
        <inertial>
            <origin xyz="1.80553e-16 -1.57546e-16 -4.20014e-16" rpy="0 0 0"/>
            <mass value="0.0493467"/>
            <inertia ixx="1.86522e-05" ixy="1.6672e-21" ixz="2.71866e-21" iyy="1.86522e-05" iyz="-2.35752e-21" izz="5.80503e-06"/>
        </inertial>
        <!-- Part roller_29_parts -->
        <collision>
            <origin xyz="6.77249e-18 -1.78993e-17 -1.86724e-16" rpy="-1.18984e-16 -8.31375e-17 1.29261e-17"/>
            <geometry>
                <sphere radius="0.0155"/>
            </geometry>
        </collision>
        <collision>
            <origin xyz="2.00938e-17 -8.95293e-18 0.0085" rpy="-1.18984e-16 -8.31375e-17 1.29261e-17"/>
            <geometry>
                <sphere radius="0.0155"/>
            </geometry>
        </collision>
        <collision>
            <origin xyz="-6.59443e-18 -2.67504e-17 -0.0085" rpy="-1.18984e-16 -8.31375e-17 1.29261e-17"/>
            <geometry>
                <sphere radius="0.0155"/>
            </geometry>
        </collision>
        <collision>
            <origin xyz="-1.28709e-18 -2.28796e-17 0.0165" rpy="-1.18984e-16 -8.31375e-17 1.29261e-17"/>
            <geometry>
                <sphere radius="0.015"/>
            </geometry>
        </collision>
        <collision>
            <origin xyz="1.56538e-17 -1.239e-17 -0.0165" rpy="-1.18984e-16 -8.31375e-17 1.29261e-17"/>
            <geometry>
                <sphere radius="0.015"/>
            </geometry>
        </collision>
        <collision>
            <origin xyz="-7.5502e-18 -6.99674e-18 0.0235" rpy="-1.18984e-16 -8.31375e-17 1.29261e-17"/>
            <geometry>
                <sphere radius="0.014"/>
            </geometry>
        </collision>
        <collision>
            <origin xyz="2.01822e-17 -2.82729e-17 -0.0235" rpy="-1.18984e-16 -8.31375e-17 1.29261e-17"/>
            <geometry>
                <sphere radius="0.014"/>
            </geometry>
        </collision>
        <visual>
            <origin xyz="1.80411e-16 -1.66533e-16 -4.16334e-16" rpy="-2.32393 -0.248666 2.50013"/>
            <geometry>
                <mesh filename="package://assets/merged/roller_29_visual.stl"/>
            </geometry>
            <material name="roller_29_parts_material">
                <color rgba="0.752941 0.752941 0.752941 1.0"/>
            </material>
        </visual>
    </link>
    <!-- Joint from front_left_wheel to roller_29 -->
    <joint name="flw_r5" type="revolute">
        <origin xyz="0.0806228 -0.0299326 0.039" rpy="2.39411 -0.268603 -0.634348"/>
        <parent link="front_left_wheel"/>
        <child link="roller_29"/>
        <axis xyz="0 0 1"/>
        <limit effort="10" velocity="10" lower="-3.141592653589793" upper="3.141592653589793"/>
    </joint>
    <!-- Link roller_30 -->
    <link name="roller_30">
        <inertial>
            <origin xyz="1.66803e-16 -2.11171e-16 -4.04665e-16" rpy="0 0 0"/>
            <mass value="0.0493467"/>
            <inertia ixx="1.86522e-05" ixy="-2.70862e-22" ixz="9.23264e-22" iyy="1.86522e-05" iyz="-2.25398e-21" izz="5.80503e-06"/>
        </inertial>
        <!-- Part roller_30_parts -->
        <collision>
            <origin xyz="-6.97759e-18 -7.1524e-17 -1.71375e-16" rpy="-1.36996e-16 -2.12657e-17 8.21069e-17"/>
            <geometry>
                <sphere radius="0.0155"/>
            </geometry>
        </collision>
        <collision>
            <origin xyz="-1.30495e-17 -7.68342e-17 0.0085" rpy="-1.36996e-16 -2.12657e-17 8.21069e-17"/>
            <geometry>
                <sphere radius="0.0155"/>
            </geometry>
        </collision>
        <collision>
            <origin xyz="-1.4885e-18 -6.61461e-17 -0.0085" rpy="-1.36996e-16 -2.12657e-17 8.21069e-17"/>
            <geometry>
                <sphere radius="0.0155"/>
            </geometry>
        </collision>
        <collision>
            <origin xyz="-1.43032e-17 -8.20283e-17 0.0165" rpy="-1.36996e-16 -2.12657e-17 8.21069e-17"/>
            <geometry>
                <sphere radius="0.015"/>
            </geometry>
        </collision>
        <collision>
            <origin xyz="1.34787e-18 -6.07842e-17 -0.0165" rpy="-1.36996e-16 -2.12657e-17 8.21069e-17"/>
            <geometry>
                <sphere radius="0.015"/>
            </geometry>
        </collision>
        <collision>
            <origin xyz="-1.3217e-17 -8.75414e-17 0.0235" rpy="-1.36996e-16 -2.12657e-17 8.21069e-17"/>
            <geometry>
                <sphere radius="0.014"/>
            </geometry>
        </collision>
        <collision>
            <origin xyz="1.02769e-18 -5.51592e-17 -0.0235" rpy="-1.36996e-16 -2.12657e-17 8.21069e-17"/>
            <geometry>
                <sphere radius="0.014"/>
            </geometry>
        </collision>
        <visual>
            <origin xyz="1.67401e-16 -2.22045e-16 -4.02456e-16" rpy="-2.13858 -0.575895 2.05017"/>
            <geometry>
                <mesh filename="package://assets/merged/roller_30_visual.stl"/>
            </geometry>
            <material name="roller_30_parts_material">
                <color rgba="0.752941 0.752941 0.752941 1.0"/>
            </material>
        </visual>
    </link>
    <!-- Joint from front_left_wheel to roller_30 -->
    <joint name="flw_r6" type="revolute">
        <origin xyz="0.0548551 -0.0662338 0.039" rpy="2.39411 -0.268603 -1.15795"/>
        <parent link="front_left_wheel"/>
        <child link="roller_30"/>
        <axis xyz="0 0 1"/>
        <limit effort="10" velocity="10" lower="-3.141592653589793" upper="3.141592653589793"/>
    </joint>
    <!-- Link roller_31 -->
    <link name="roller_31">
        <inertial>
            <origin xyz="1.60321e-16 -1.37002e-16 -3.59984e-16" rpy="0 0 0"/>
            <mass value="0.0493467"/>
            <inertia ixx="1.86522e-05" ixy="-3.86851e-22" ixz="1.47532e-21" iyy="1.86522e-05" iyz="-1.9187e-21" izz="5.80503e-06"/>
        </inertial>
        <!-- Part roller_31_parts -->
        <collision>
            <origin xyz="-1.3459e-17 2.64519e-18 -1.26693e-16" rpy="-1.69724e-16 -7.32e-17 1.07099e-17"/>
            <geometry>
                <sphere radius="0.0155"/>
            </geometry>
        </collision>
        <collision>
            <origin xyz="-5.7228e-18 3.71236e-17 0.0085" rpy="-1.69724e-16 -7.32e-17 1.07099e-17"/>
            <geometry>
                <sphere radius="0.0155"/>
            </geometry>
        </collision>
        <collision>
            <origin xyz="-1.82765e-17 -1.25502e-17 -0.0085" rpy="-1.69724e-16 -7.32e-17 1.07099e-17"/>
            <geometry>
                <sphere radius="0.0155"/>
            </geometry>
        </collision>
        <collision>
            <origin xyz="-1.34679e-17 -1.51138e-18 0.0165" rpy="-1.69724e-16 -7.32e-17 1.07099e-17"/>
            <geometry>
                <sphere radius="0.015"/>
            </geometry>
        </collision>
        <collision>
            <origin xyz="-1.62777e-17 -1.21333e-17 -0.0165" rpy="-1.69724e-16 -7.32e-17 1.07099e-17"/>
            <geometry>
                <sphere radius="0.015"/>
            </geometry>
        </collision>
        <collision>
            <origin xyz="-1.53203e-17 3.0206e-18 0.0235" rpy="-1.69724e-16 -7.32e-17 1.07099e-17"/>
            <geometry>
                <sphere radius="0.014"/>
            </geometry>
        </collision>
        <collision>
            <origin xyz="-1.18232e-17 2.41665e-18 -0.0235" rpy="-1.69724e-16 -7.32e-17 1.07099e-17"/>
            <geometry>
                <sphere radius="0.014"/>
            </geometry>
        </collision>
        <visual>
            <origin xyz="1.52656e-16 -1.66533e-16 -3.7817e-16" rpy="-1.73657 -0.771399 1.42161"/>
            <geometry>
                <mesh filename="package://assets/merged/roller_31_visual.stl"/>
            </geometry>
            <material name="roller_31_parts_material">
                <color rgba="0.752941 0.752941 0.752941 1.0"/>
            </material>
        </visual>
    </link>
    <!-- Joint from front_left_wheel to roller_31 -->
    <joint name="flw_r7" type="revolute">
        <origin xyz="0.014389 -0.0847877 0.039" rpy="2.39411 -0.268603 -1.68155"/>
        <parent link="front_left_wheel"/>
        <child link="roller_31"/>
        <axis xyz="0 0 1"/>
        <limit effort="10" velocity="10" lower="-3.141592653589793" upper="3.141592653589793"/>
    </joint>
    <!-- Link roller_32 -->
    <link name="roller_32">
        <inertial>
            <origin xyz="1.6144e-16 -1.10761e-16 -3.92337e-16" rpy="0 0 0"/>
            <mass value="0.0493467"/>
            <inertia ixx="1.86522e-05" ixy="-4.5375e-21" ixz="-1.23035e-22" iyy="1.86522e-05" iyz="-4.1253e-21" izz="5.80503e-06"/>
        </inertial>
        <!-- Part roller_32_parts -->
        <collision>
            <origin xyz="-1.23408e-17 2.88855e-17 -1.59047e-16" rpy="-2.86613e-16 -4.49673e-17 -2.74366e-17"/>
            <geometry>
                <sphere radius="0.0155"/>
            </geometry>
        </collision>
        <collision>
            <origin xyz="-2.32703e-17 1.86326e-17 0.0085" rpy="-2.86613e-16 -4.49673e-17 -2.74366e-17"/>
            <geometry>
                <sphere radius="0.0155"/>
            </geometry>
        </collision>
        <collision>
            <origin xyz="-1.27288e-18 3.86456e-17 -0.0085" rpy="-2.86613e-16 -4.49673e-17 -2.74366e-17"/>
            <geometry>
                <sphere radius="0.0155"/>
            </geometry>
        </collision>
        <collision>
            <origin xyz="-2.33687e-17 2.44119e-17 0.0165" rpy="-2.86613e-16 -4.49673e-17 -2.74366e-17"/>
            <geometry>
                <sphere radius="0.015"/>
            </geometry>
        </collision>
        <collision>
            <origin xyz="-1.6082e-18 3.28663e-17 -0.0165" rpy="-2.86613e-16 -4.49673e-17 -2.74366e-17"/>
            <geometry>
                <sphere radius="0.015"/>
            </geometry>
        </collision>
        <collision>
            <origin xyz="-1.74957e-17 2.53336e-17 0.0235" rpy="-2.86613e-16 -4.49673e-17 -2.74366e-17"/>
            <geometry>
                <sphere radius="0.014"/>
            </geometry>
        </collision>
        <collision>
            <origin xyz="-7.48118e-18 3.28119e-17 -0.0235" rpy="-2.86613e-16 -4.49673e-17 -2.74366e-17"/>
            <geometry>
                <sphere radius="0.014"/>
            </geometry>
        </collision>
        <visual>
            <origin xyz="1.66533e-16 -1.11022e-16 -3.78603e-16" rpy="-1.23586 -0.724678 0.702578"/>
            <geometry>
                <mesh filename="package://assets/merged/roller_32_visual.stl"/>
            </geometry>
            <material name="roller_32_parts_material">
                <color rgba="0.752941 0.752941 0.752941 1.0"/>
            </material>
        </visual>
    </link>
    <!-- Joint from front_left_wheel to roller_32 -->
    <joint name="flw_r8" type="revolute">
        <origin xyz="-0.0299326 -0.0806228 0.039" rpy="2.39411 -0.268603 -2.20514"/>
        <parent link="front_left_wheel"/>
        <child link="roller_32"/>
        <axis xyz="0 0 1"/>
        <limit effort="10" velocity="10" lower="-3.141592653589793" upper="3.141592653589793"/>
    </joint>
    <!-- Link roller_33 -->
    <link name="roller_33">
        <inertial>
            <origin xyz="2.56757e-16 -1.90533e-16 -4.04967e-16" rpy="0 0 0"/>
            <mass value="0.0493467"/>
            <inertia ixx="1.86522e-05" ixy="9.18946e-22" ixz="1.04824e-21" iyy="1.86522e-05" iyz="-2.30743e-21" izz="5.80503e-06"/>
        </inertial>
        <!-- Part roller_33_parts -->
        <collision>
            <origin xyz="8.29765e-17 -5.08862e-17 -1.71676e-16" rpy="-1.99437e-16 -1.01776e-16 4.47485e-17"/>
            <geometry>
                <sphere radius="0.0155"/>
            </geometry>
        </collision>
        <collision>
            <origin xyz="6.89624e-17 -6.24012e-17 0.0085" rpy="-1.99437e-16 -1.01776e-16 4.47485e-17"/>
            <geometry>
                <sphere radius="0.0155"/>
            </geometry>
        </collision>
        <collision>
            <origin xyz="9.66378e-17 -3.88995e-17 -0.0085" rpy="-1.99437e-16 -1.01776e-16 4.47485e-17"/>
            <geometry>
                <sphere radius="0.0155"/>
            </geometry>
        </collision>
        <collision>
            <origin xyz="6.1008e-17 -5.98162e-17 0.0165" rpy="-1.99437e-16 -1.01776e-16 4.47485e-17"/>
            <geometry>
                <sphere radius="0.015"/>
            </geometry>
        </collision>
        <collision>
            <origin xyz="1.04257e-16 -4.04053e-17 -0.0165" rpy="-1.99437e-16 -1.01776e-16 4.47485e-17"/>
            <geometry>
                <sphere radius="0.015"/>
            </geometry>
        </collision>
        <collision>
            <origin xyz="6.78401e-17 -3.61034e-17 0.0235" rpy="-1.99437e-16 -1.01776e-16 4.47485e-17"/>
            <geometry>
                <sphere radius="0.014"/>
            </geometry>
        </collision>
        <collision>
            <origin xyz="9.87666e-17 -6.84347e-17 -0.0235" rpy="-1.99437e-16 -1.01776e-16 4.47485e-17"/>
            <geometry>
                <sphere radius="0.014"/>
            </geometry>
        </collision>
        <visual>
            <origin xyz="2.77556e-16 -1.94289e-16 -3.88578e-16" rpy="-0.914517 -0.467917 0.145054"/>
            <geometry>
                <mesh filename="package://assets/merged/roller_33_visual.stl"/>
            </geometry>
            <material name="roller_33_parts_material">
                <color rgba="0.752941 0.752941 0.752941 1.0"/>
            </material>
        </visual>
    </link>
    <!-- Joint from front_left_wheel to roller_33 -->
    <joint name="flw_r9" type="revolute">
        <origin xyz="-0.0662338 -0.0548551 0.039" rpy="2.39411 -0.268603 -2.72874"/>
        <parent link="front_left_wheel"/>
        <child link="roller_33"/>
        <axis xyz="0 0 1"/>
        <limit effort="10" velocity="10" lower="-3.141592653589793" upper="3.141592653589793"/>
    </joint>
    <!-- Link roller_34 -->
    <link name="roller_34">
        <inertial>
            <origin xyz="1.90357e-16 -1.13228e-16 -4.19441e-16" rpy="0 0 0"/>
            <mass value="0.0493467"/>
            <inertia ixx="1.86522e-05" ixy="-1.28407e-21" ixz="2.22014e-21" iyy="1.86522e-05" iyz="-2.01242e-21" izz="5.80503e-06"/>
        </inertial>
        <!-- Part roller_34_parts -->
        <collision>
            <origin xyz="1.65764e-17 2.64185e-17 -1.86151e-16" rpy="-2.11717e-16 -1.93428e-16 -4.70822e-17"/>
            <geometry>
                <sphere radius="0.0155"/>
            </geometry>
        </collision>
        <collision>
            <origin xyz="-1.64436e-18 2.08921e-17 0.0085" rpy="-2.11717e-16 -1.93428e-16 -4.70822e-17"/>
            <geometry>
                <sphere radius="0.0155"/>
            </geometry>
        </collision>
        <collision>
            <origin xyz="3.50989e-17 3.20026e-17 -0.0085" rpy="-2.11717e-16 -1.93428e-16 -4.70822e-17"/>
            <geometry>
                <sphere radius="0.0155"/>
            </geometry>
        </collision>
        <collision>
            <origin xyz="1.04911e-17 1.86923e-17 0.0165" rpy="-2.11717e-16 -1.93428e-16 -4.70822e-17"/>
            <geometry>
                <sphere radius="0.015"/>
            </geometry>
        </collision>
        <collision>
            <origin xyz="2.38308e-17 3.4094e-17 -0.0165" rpy="-2.11717e-16 -1.93428e-16 -4.70822e-17"/>
            <geometry>
                <sphere radius="0.015"/>
            </geometry>
        </collision>
        <collision>
            <origin xyz="7.61497e-20 5.44977e-17 0.0235" rpy="-2.11717e-16 -1.93428e-16 -4.70822e-17"/>
            <geometry>
                <sphere radius="0.014"/>
            </geometry>
        </collision>
        <collision>
            <origin xyz="3.25111e-17 -1.92826e-18 -0.0235" rpy="-2.11717e-16 -1.93428e-16 -4.70822e-17"/>
            <geometry>
                <sphere radius="0.014"/>
            </geometry>
        </collision>
        <visual>
            <origin xyz="1.94289e-16 -1.11022e-16 -4.02456e-16" rpy="-0.792496 -0.118587 1.30549"/>
            <geometry>
                <mesh filename="package://assets/merged/roller_34_visual.stl"/>
            </geometry>
            <material name="roller_34_parts_material">
                <color rgba="0.752941 0.752941 0.752941 1.0"/>
            </material>
        </visual>
    </link>
    <!-- Joint from front_left_wheel to roller_34 -->
    <joint name="flw_r10" type="revolute">
        <origin xyz="-0.0847877 -0.014389 0.039" rpy="2.78255 0.714734 -1.92274"/>
        <parent link="front_left_wheel"/>
        <child link="roller_34"/>
        <axis xyz="0 0 1"/>
        <limit effort="10" velocity="10" lower="-3.141592653589793" upper="3.141592653589793"/>
    </joint>
    <!-- Link roller_35 -->
    <link name="roller_35">
        <inertial>
            <origin xyz="1.39815e-16 -1.11392e-16 -3.96618e-16" rpy="0 0 0"/>
            <mass value="0.0493467"/>
            <inertia ixx="1.86522e-05" ixy="-8.75182e-22" ixz="-1.78519e-21" iyy="1.86522e-05" iyz="-1.24946e-21" izz="5.80503e-06"/>
        </inertial>
        <!-- Part roller_35_parts -->
        <collision>
            <origin xyz="-3.39652e-17 2.82543e-17 -1.63327e-16" rpy="-1.22865e-16 -7.42479e-18 -9.46757e-17"/>
            <geometry>
                <sphere radius="0.0155"/>
            </geometry>
        </collision>
        <collision>
            <origin xyz="-7.64692e-18 4.03482e-17 0.0085" rpy="-1.22865e-16 -7.42479e-18 -9.46757e-17"/>
            <geometry>
                <sphere radius="0.0155"/>
            </geometry>
        </collision>
        <collision>
            <origin xyz="-6.0513e-17 1.60752e-17 -0.0085" rpy="-1.22865e-16 -7.42479e-18 -9.46757e-17"/>
            <geometry>
                <sphere radius="0.0155"/>
            </geometry>
        </collision>
        <collision>
            <origin xyz="-3.14725e-17 2.77503e-17 0.0165" rpy="-1.22865e-16 -7.42479e-18 -9.46757e-17"/>
            <geometry>
                <sphere radius="0.015"/>
            </geometry>
        </collision>
        <collision>
            <origin xyz="-3.62537e-17 2.82394e-17 -0.0165" rpy="-1.22865e-16 -7.42479e-18 -9.46757e-17"/>
            <geometry>
                <sphere radius="0.015"/>
            </geometry>
        </collision>
        <collision>
            <origin xyz="-3.50589e-17 1.38852e-17 0.0235" rpy="-1.22865e-16 -7.42479e-18 -9.46757e-17"/>
            <geometry>
                <sphere radius="0.014"/>
            </geometry>
        </collision>
        <collision>
            <origin xyz="-3.26673e-17 4.21045e-17 -0.0235" rpy="-1.22865e-16 -7.42479e-18 -9.46757e-17"/>
            <geometry>
                <sphere radius="0.014"/>
            </geometry>
        </collision>
        <visual>
            <origin xyz="1.52656e-16 -1.11022e-16 -3.88578e-16" rpy="-0.817659 0.248666 0.929333"/>
            <geometry>
                <mesh filename="package://assets/merged/roller_35_visual.stl"/>
            </geometry>
            <material name="roller_35_parts_material">
                <color rgba="0.752941 0.752941 0.752941 1.0"/>
            </material>
        </visual>
    </link>
    <!-- Joint from front_left_wheel to roller_35 -->
    <joint name="flw_r11" type="revolute">
        <origin xyz="-0.0806228 0.0299326 0.039" rpy="2.78255 0.714734 -2.44634"/>
        <parent link="front_left_wheel"/>
        <child link="roller_35"/>
        <axis xyz="0 0 1"/>
        <limit effort="10" velocity="10" lower="-3.141592653589793" upper="3.141592653589793"/>
    </joint>
    <!-- Link roller_36 -->
    <link name="roller_36">
        <inertial>
            <origin xyz="1.56403e-16 -9.44821e-17 -4.1851e-16" rpy="0 0 0"/>
            <mass value="0.0493467"/>
            <inertia ixx="1.86522e-05" ixy="-1.72158e-21" ixz="3.87726e-22" iyy="1.86522e-05" iyz="-4.50657e-21" izz="5.80503e-06"/>
        </inertial>
        <!-- Part roller_36_parts -->
        <collision>
            <origin xyz="-1.73773e-17 4.51646e-17 -1.85219e-16" rpy="-2.98331e-16 -8.12266e-17 -8.32951e-18"/>
            <geometry>
                <sphere radius="0.0155"/>
            </geometry>
        </collision>
        <collision>
            <origin xyz="-2.77571e-17 4.78748e-17 0.0085" rpy="-2.98331e-16 -8.12266e-17 -8.32951e-18"/>
            <geometry>
                <sphere radius="0.0155"/>
            </geometry>
        </collision>
        <collision>
            <origin xyz="-6.77157e-18 4.24928e-17 -0.0085" rpy="-2.98331e-16 -8.12266e-17 -8.32951e-18"/>
            <geometry>
                <sphere radius="0.0155"/>
            </geometry>
        </collision>
        <collision>
            <origin xyz="-1.85821e-18 5.8781e-17 0.0165" rpy="-2.98331e-16 -8.12266e-17 -8.32951e-18"/>
            <geometry>
                <sphere radius="0.015"/>
            </geometry>
        </collision>
        <collision>
            <origin xyz="-3.22368e-17 3.1153e-17 -0.0165" rpy="-2.98331e-16 -8.12266e-17 -8.32951e-18"/>
            <geometry>
                <sphere radius="0.015"/>
            </geometry>
        </collision>
        <collision>
            <origin xyz="1.40861e-18 5.62112e-17 0.0235" rpy="-2.98331e-16 -8.12266e-17 -8.32951e-18"/>
            <geometry>
                <sphere radius="0.014"/>
            </geometry>
        </collision>
        <collision>
            <origin xyz="-3.81613e-17 4.6846e-17 -0.0235" rpy="-2.98331e-16 -8.12266e-17 -8.32951e-18"/>
            <geometry>
                <sphere radius="0.014"/>
            </geometry>
        </collision>
        <visual>
            <origin xyz="1.38778e-16 -1.11022e-16 -3.88578e-16" rpy="-1.00301 0.575895 0.479378"/>
            <geometry>
                <mesh filename="package://assets/merged/roller_36_visual.stl"/>
            </geometry>
            <material name="roller_36_parts_material">
                <color rgba="0.752941 0.752941 0.752941 1.0"/>
            </material>
        </visual>
    </link>
    <!-- Joint from front_left_wheel to roller_36 -->
    <joint name="flw_r12" type="revolute">
        <origin xyz="-0.0548551 0.0662338 0.039" rpy="2.78255 0.714734 -2.96994"/>
        <parent link="front_left_wheel"/>
        <child link="roller_36"/>
        <axis xyz="0 0 1"/>
        <limit effort="10" velocity="10" lower="-3.141592653589793" upper="3.141592653589793"/>
    </joint>
    <!-- Joint from base_link to front_left_wheel -->
    <joint name="front_left_wheel" type="continuous">
        <origin xyz="0.2685 0.24 0.065" rpy="1.5708 -6.32034e-16 -3.14159"/>
        <parent link="base_link"/>
        <child link="front_left_wheel"/>
        <axis xyz="0 0 1"/>
        <limit effort="10" velocity="10"/>
    </joint>
    <!-- Link back_right_wheel -->
    <link name="back_right_wheel">
        <inertial>
            <origin xyz="3.47124e-06 -2.04529e-05 -0.038998" rpy="0 0 0"/>
            <mass value="0.942157"/>
            <inertia ixx="0.00202095" ixy="-9.22565e-07" ixz="7.0304e-12" iyy="0.00202623" iyz="-7.62497e-11" izz="0.00255146"/>
        </inertial>
        <!-- Part back_right_wheel_parts -->
        <visual>
            <origin xyz="3.47124e-06 -2.04529e-05 -0.038998" rpy="1.5708 3.39654e-15 -3.14159"/>
            <geometry>
                <mesh filename="package://assets/merged/back_right_wheel_visual.stl"/>
            </geometry>
            <material name="back_right_wheel_parts_material">
                <color rgba="0.792157 0.819608 0.933333 1.0"/>
            </material>
        </visual>
    </link>
    <!-- Link roller_37 -->
    <link name="roller_37">
        <inertial>
            <origin xyz="1.31529e-16 -1.58312e-16 -3.87384e-16" rpy="0 0 0"/>
            <mass value="0.0493467"/>
            <inertia ixx="1.86522e-05" ixy="-1.99149e-21" ixz="3.1875e-21" iyy="1.86522e-05" iyz="-3.73633e-21" izz="5.80503e-06"/>
        </inertial>
        <!-- Part roller_37_parts -->
        <collision>
            <origin xyz="-4.22515e-17 -1.86651e-17 -1.54093e-16" rpy="-1.90456e-16 -9.30795e-17 -5.0821e-17"/>
            <geometry>
                <sphere radius="0.0155"/>
            </geometry>
        </collision>
        <collision>
            <origin xyz="-6.19633e-17 -3.67963e-18 0.0085" rpy="-1.90456e-16 -9.30795e-17 -5.0821e-17"/>
            <geometry>
                <sphere radius="0.0155"/>
            </geometry>
        </collision>
        <collision>
            <origin xyz="-2.25056e-17 -3.36689e-17 -0.0085" rpy="-1.90456e-16 -9.30795e-17 -5.0821e-17"/>
            <geometry>
                <sphere radius="0.0155"/>
            </geometry>
        </collision>
        <collision>
            <origin xyz="-4.57406e-17 -2.54384e-17 0.0165" rpy="-1.90456e-16 -9.30795e-17 -5.0821e-17"/>
            <geometry>
                <sphere radius="0.015"/>
            </geometry>
        </collision>
        <collision>
            <origin xyz="-3.31431e-17 -2.18038e-17 -0.0165" rpy="-1.90456e-16 -9.30795e-17 -5.0821e-17"/>
            <geometry>
                <sphere radius="0.015"/>
            </geometry>
        </collision>
        <collision>
            <origin xyz="-2.27784e-17 -5.94045e-18 0.0235" rpy="-1.90456e-16 -9.30795e-17 -5.0821e-17"/>
            <geometry>
                <sphere radius="0.014"/>
            </geometry>
        </collision>
        <collision>
            <origin xyz="-6.77095e-17 -2.23817e-17 -0.0235" rpy="-1.90456e-16 -9.30795e-17 -5.0821e-17"/>
            <geometry>
                <sphere radius="0.014"/>
            </geometry>
        </collision>
        <visual>
            <origin xyz="1.11022e-16 -1.66533e-16 -3.88578e-16" rpy="-2.22708 0.467917 0.145054"/>
            <geometry>
                <mesh filename="package://assets/merged/roller_37_visual.stl"/>
            </geometry>
            <material name="roller_37_parts_material">
                <color rgba="0.752941 0.752941 0.752941 1.0"/>
            </material>
        </visual>
    </link>
    <!-- Joint from back_right_wheel to roller_37 -->
    <joint name="brw_r1" type="revolute">
        <origin xyz="0.0662338 0.0548551 -0.039" rpy="-2.39411 0.268603 -2.72874"/>
        <parent link="back_right_wheel"/>
        <child link="roller_37"/>
        <axis xyz="0 0 1"/>
        <limit effort="10" velocity="10" lower="-3.141592653589793" upper="3.141592653589793"/>
    </joint>
    <!-- Link roller_38 -->
    <link name="roller_38">
        <inertial>
            <origin xyz="1.56147e-16 -1.67554e-16 -3.73572e-16" rpy="0 0 0"/>
            <mass value="0.0493467"/>
            <inertia ixx="1.86522e-05" ixy="1.39178e-21" ixz="5.30789e-21" iyy="1.86522e-05" iyz="-2.91671e-21" izz="5.80503e-06"/>
        </inertial>
        <!-- Part roller_38_parts -->
        <collision>
            <origin xyz="-1.76334e-17 -2.79075e-17 -1.40282e-16" rpy="-2.02577e-16 -2.58384e-16 5.12685e-17"/>
            <geometry>
                <sphere radius="0.0155"/>
            </geometry>
        </collision>
        <collision>
            <origin xyz="-1.46962e-17 -1.4449e-17 0.0085" rpy="-2.02577e-16 -2.58384e-16 5.12685e-17"/>
            <geometry>
                <sphere radius="0.0155"/>
            </geometry>
        </collision>
        <collision>
            <origin xyz="-2.0541e-17 -4.13395e-17 -0.0085" rpy="-2.02577e-16 -2.58384e-16 5.12685e-17"/>
            <geometry>
                <sphere radius="0.0155"/>
            </geometry>
        </collision>
        <collision>
            <origin xyz="-2.42992e-17 -9.46905e-18 0.0165" rpy="-2.02577e-16 -2.58384e-16 5.12685e-17"/>
            <geometry>
                <sphere radius="0.015"/>
            </geometry>
        </collision>
        <collision>
            <origin xyz="-1.0938e-17 -4.65364e-17 -0.0165" rpy="-2.02577e-16 -2.58384e-16 5.12685e-17"/>
            <geometry>
                <sphere radius="0.015"/>
            </geometry>
        </collision>
        <collision>
            <origin xyz="-3.75401e-17 -2.36183e-17 0.0235" rpy="-2.02577e-16 -2.58384e-16 5.12685e-17"/>
            <geometry>
                <sphere radius="0.014"/>
            </geometry>
        </collision>
        <collision>
            <origin xyz="2.30286e-18 -3.23871e-17 -0.0235" rpy="-2.02577e-16 -2.58384e-16 5.12685e-17"/>
            <geometry>
                <sphere radius="0.014"/>
            </geometry>
        </collision>
        <visual>
            <origin xyz="1.66533e-16 -1.66533e-16 -3.88578e-16" rpy="-2.3491 0.118587 1.30549"/>
            <geometry>
                <mesh filename="package://assets/merged/roller_38_visual.stl"/>
            </geometry>
            <material name="roller_38_parts_material">
                <color rgba="0.752941 0.752941 0.752941 1.0"/>
            </material>
        </visual>
    </link>
    <!-- Joint from back_right_wheel to roller_38 -->
    <joint name="brw_r2" type="revolute">
        <origin xyz="0.0847877 0.014389 -0.039" rpy="-2.78255 -0.714734 -1.92274"/>
        <parent link="back_right_wheel"/>
        <child link="roller_38"/>
        <axis xyz="0 0 1"/>
        <limit effort="10" velocity="10" lower="-3.141592653589793" upper="3.141592653589793"/>
    </joint>
    <!-- Link roller_39 -->
    <link name="roller_39">
        <inertial>
            <origin xyz="2.61876e-16 -1.15205e-16 -4.05048e-16" rpy="0 0 0"/>
            <mass value="0.0493467"/>
            <inertia ixx="1.86522e-05" ixy="2.15883e-21" ixz="-1.72789e-22" iyy="1.86522e-05" iyz="-2.64566e-21" izz="5.80503e-06"/>
        </inertial>
        <!-- Part roller_39_parts -->
        <collision>
            <origin xyz="8.80955e-17 2.4442e-17 -1.71758e-16" rpy="-1.7888e-16 -1.00461e-16 4.89569e-17"/>
            <geometry>
                <sphere radius="0.0155"/>
            </geometry>
        </collision>
        <collision>
            <origin xyz="7.58009e-17 3.40384e-17 0.0085" rpy="-1.7888e-16 -1.00461e-16 4.89569e-17"/>
            <geometry>
                <sphere radius="0.0155"/>
            </geometry>
        </collision>
        <collision>
            <origin xyz="9.88197e-17 1.66399e-17 -0.0085" rpy="-1.7888e-16 -1.00461e-16 4.89569e-17"/>
            <geometry>
                <sphere radius="0.0155"/>
            </geometry>
        </collision>
        <collision>
            <origin xyz="9.91084e-17 2.88874e-17 0.0165" rpy="-1.7888e-16 -1.00461e-16 4.89569e-17"/>
            <geometry>
                <sphere radius="0.015"/>
            </geometry>
        </collision>
        <collision>
            <origin xyz="7.55122e-17 2.26582e-17 -0.0165" rpy="-1.7888e-16 -1.00461e-16 4.89569e-17"/>
            <geometry>
                <sphere radius="0.015"/>
            </geometry>
        </collision>
        <collision>
            <origin xyz="8.2762e-17 3.94043e-17 0.0235" rpy="-1.7888e-16 -1.00461e-16 4.89569e-17"/>
            <geometry>
                <sphere radius="0.014"/>
            </geometry>
        </collision>
        <collision>
            <origin xyz="9.35371e-17 1.01588e-17 -0.0235" rpy="-1.7888e-16 -1.00461e-16 4.89569e-17"/>
            <geometry>
                <sphere radius="0.014"/>
            </geometry>
        </collision>
        <visual>
            <origin xyz="2.77556e-16 -1.11022e-16 -4.16334e-16" rpy="-2.32393 -0.248666 0.929333"/>
            <geometry>
                <mesh filename="package://assets/merged/roller_39_visual.stl"/>
            </geometry>
            <material name="roller_39_parts_material">
                <color rgba="0.752941 0.752941 0.752941 1.0"/>
            </material>
        </visual>
    </link>
    <!-- Joint from back_right_wheel to roller_39 -->
    <joint name="brw_r3" type="revolute">
        <origin xyz="0.0806228 -0.0299326 -0.039" rpy="-2.78255 -0.714734 -2.44634"/>
        <parent link="back_right_wheel"/>
        <child link="roller_39"/>
        <axis xyz="0 0 1"/>
        <limit effort="10" velocity="10" lower="-3.141592653589793" upper="3.141592653589793"/>
    </joint>
    <!-- Link roller_40 -->
    <link name="roller_40">
        <inertial>
            <origin xyz="8.8382e-17 -1.25154e-16 -3.96224e-16" rpy="0 0 0"/>
            <mass value="0.0493467"/>
            <inertia ixx="1.86522e-05" ixy="-2.37918e-21" ixz="1.22617e-21" iyy="1.86522e-05" iyz="-9.70584e-22" izz="5.80503e-06"/>
        </inertial>
        <!-- Part roller_40_parts -->
        <collision>
            <origin xyz="-8.53984e-17 1.44928e-17 -1.62934e-16" rpy="-1.50456e-16 -1.19113e-16 -2.68165e-17"/>
            <geometry>
                <sphere radius="0.0155"/>
            </geometry>
        </collision>
        <collision>
            <origin xyz="-1.16363e-16 1.00737e-17 0.0085" rpy="-1.50456e-16 -1.19113e-16 -2.68165e-17"/>
            <geometry>
                <sphere radius="0.0155"/>
            </geometry>
        </collision>
        <collision>
            <origin xyz="-5.43971e-17 1.86635e-17 -0.0085" rpy="-1.50456e-16 -1.19113e-16 -2.68165e-17"/>
            <geometry>
                <sphere radius="0.0155"/>
            </geometry>
        </collision>
        <collision>
            <origin xyz="-1.04435e-16 2.63309e-17 0.0165" rpy="-1.50456e-16 -1.19113e-16 -2.68165e-17"/>
            <geometry>
                <sphere radius="0.015"/>
            </geometry>
        </collision>
        <collision>
            <origin xyz="-6.60034e-17 3.17226e-18 -0.0165" rpy="-1.50456e-16 -1.19113e-16 -2.68165e-17"/>
            <geometry>
                <sphere radius="0.015"/>
            </geometry>
        </collision>
        <collision>
            <origin xyz="-9.04902e-17 3.91247e-17 0.0235" rpy="-1.50456e-16 -1.19113e-16 -2.68165e-17"/>
            <geometry>
                <sphere radius="0.014"/>
            </geometry>
        </collision>
        <collision>
            <origin xyz="-8.11475e-17 -8.95692e-18 -0.0235" rpy="-1.50456e-16 -1.19113e-16 -2.68165e-17"/>
            <geometry>
                <sphere radius="0.014"/>
            </geometry>
        </collision>
        <visual>
            <origin xyz="5.55112e-17 -1.52656e-16 -4.4062e-16" rpy="-2.13858 -0.575895 0.479378"/>
            <geometry>
                <mesh filename="package://assets/merged/roller_40_visual.stl"/>
            </geometry>
            <material name="roller_40_parts_material">
                <color rgba="0.752941 0.752941 0.752941 1.0"/>
            </material>
        </visual>
    </link>
    <!-- Joint from back_right_wheel to roller_40 -->
    <joint name="brw_r4" type="revolute">
        <origin xyz="0.0548551 -0.0662338 -0.039" rpy="-2.78255 -0.714734 -2.96994"/>
        <parent link="back_right_wheel"/>
        <child link="roller_40"/>
        <axis xyz="0 0 1"/>
        <limit effort="10" velocity="10" lower="-3.141592653589793" upper="3.141592653589793"/>
    </joint>
    <!-- Link roller_41 -->
    <link name="roller_41">
        <inertial>
            <origin xyz="1.88077e-16 -1.37002e-16 -4.31758e-16" rpy="0 0 0"/>
            <mass value="0.0493467"/>
            <inertia ixx="1.86522e-05" ixy="4.93314e-22" ixz="8.57359e-22" iyy="1.86522e-05" iyz="-3.8073e-21" izz="5.80503e-06"/>
        </inertial>
        <!-- Part roller_41_parts -->
        <collision>
            <origin xyz="1.42966e-17 2.64519e-18 -1.98468e-16" rpy="-1.56707e-16 -6.86889e-17 -1.37685e-17"/>
            <geometry>
                <sphere radius="0.0155"/>
            </geometry>
        </collision>
        <collision>
            <origin xyz="1.62635e-17 1.95562e-17 0.0085" rpy="-1.56707e-16 -6.86889e-17 -1.37685e-17"/>
            <geometry>
                <sphere radius="0.0155"/>
            </geometry>
        </collision>
        <collision>
            <origin xyz="1.2321e-17 -1.40647e-17 -0.0085" rpy="-1.56707e-16 -6.86889e-17 -1.37685e-17"/>
            <geometry>
                <sphere radius="0.0155"/>
            </geometry>
        </collision>
        <collision>
            <origin xyz="6.49436e-18 2.73909e-18 0.0165" rpy="-1.56707e-16 -6.86889e-17 -1.37685e-17"/>
            <geometry>
                <sphere radius="0.015"/>
            </geometry>
        </collision>
        <collision>
            <origin xyz="2.20901e-17 2.80657e-18 -0.0165" rpy="-1.56707e-16 -6.86889e-17 -1.37685e-17"/>
            <geometry>
                <sphere radius="0.015"/>
            </geometry>
        </collision>
        <collision>
            <origin xyz="1.76968e-17 2.6816e-17 0.0235" rpy="-1.56707e-16 -6.86889e-17 -1.37685e-17"/>
            <geometry>
                <sphere radius="0.014"/>
            </geometry>
        </collision>
        <collision>
            <origin xyz="1.06708e-17 -2.30051e-17 -0.0235" rpy="-1.56707e-16 -6.86889e-17 -1.37685e-17"/>
            <geometry>
                <sphere radius="0.014"/>
            </geometry>
        </collision>
        <visual>
            <origin xyz="1.80411e-16 -1.66533e-16 -4.49944e-16" rpy="-1.73657 -0.771399 1.42161"/>
            <geometry>
                <mesh filename="package://assets/merged/roller_41_visual.stl"/>
            </geometry>
            <material name="roller_41_parts_material">
                <color rgba="0.752941 0.752941 0.752941 1.0"/>
            </material>
        </visual>
    </link>
    <!-- Joint from back_right_wheel to roller_41 -->
    <joint name="brw_r5" type="revolute">
        <origin xyz="0.014389 -0.0847877 -0.039" rpy="2.39411 -0.268603 -1.68155"/>
        <parent link="back_right_wheel"/>
        <child link="roller_41"/>
        <axis xyz="0 0 1"/>
        <limit effort="10" velocity="10" lower="-3.141592653589793" upper="3.141592653589793"/>
    </joint>
    <!-- Link roller_42 -->
    <link name="roller_42">
        <inertial>
            <origin xyz="1.50891e-16 -1.5385e-16 -3.98218e-16" rpy="0 0 0"/>
            <mass value="0.0493467"/>
            <inertia ixx="1.86522e-05" ixy="1.01423e-21" ixz="1.79814e-21" iyy="1.86522e-05" iyz="-3.14789e-21" izz="5.80503e-06"/>
        </inertial>
        <!-- Part roller_42_parts -->
        <collision>
            <origin xyz="-2.28896e-17 -1.42033e-17 -1.64927e-16" rpy="-1.77566e-16 -7.40169e-17 2.13461e-17"/>
            <geometry>
                <sphere radius="0.0155"/>
            </geometry>
        </collision>
        <collision>
            <origin xyz="-3.64878e-17 -3.25047e-17 0.0085" rpy="-1.77566e-16 -7.40169e-17 2.13461e-17"/>
            <geometry>
                <sphere radius="0.0155"/>
            </geometry>
        </collision>
        <collision>
            <origin xyz="-1.07775e-17 5.29324e-18 -0.0085" rpy="-1.77566e-16 -7.40169e-17 2.13461e-17"/>
            <geometry>
                <sphere radius="0.0155"/>
            </geometry>
        </collision>
        <collision>
            <origin xyz="-2.39744e-17 1.37063e-18 0.0165" rpy="-1.77566e-16 -7.40169e-17 2.13461e-17"/>
            <geometry>
                <sphere radius="0.015"/>
            </geometry>
        </collision>
        <collision>
            <origin xyz="-1.99461e-17 -3.03774e-17 -0.0165" rpy="-1.77566e-16 -7.40169e-17 2.13461e-17"/>
            <geometry>
                <sphere radius="0.015"/>
            </geometry>
        </collision>
        <collision>
            <origin xyz="-2.03551e-17 -3.62113e-18 0.0235" rpy="-1.77566e-16 -7.40169e-17 2.13461e-17"/>
            <geometry>
                <sphere radius="0.014"/>
            </geometry>
        </collision>
        <collision>
            <origin xyz="-2.62136e-17 -2.43796e-17 -0.0235" rpy="-1.77566e-16 -7.40169e-17 2.13461e-17"/>
            <geometry>
                <sphere radius="0.014"/>
            </geometry>
        </collision>
        <visual>
            <origin xyz="1.38778e-16 -1.66533e-16 -4.02456e-16" rpy="-1.23586 -0.724678 0.702578"/>
            <geometry>
                <mesh filename="package://assets/merged/roller_42_visual.stl"/>
            </geometry>
            <material name="roller_42_parts_material">
                <color rgba="0.752941 0.752941 0.752941 1.0"/>
            </material>
        </visual>
    </link>
    <!-- Joint from back_right_wheel to roller_42 -->
    <joint name="brw_r6" type="revolute">
        <origin xyz="-0.0299326 -0.0806228 -0.039" rpy="2.39411 -0.268603 -2.20514"/>
        <parent link="back_right_wheel"/>
        <child link="roller_42"/>
        <axis xyz="0 0 1"/>
        <limit effort="10" velocity="10" lower="-3.141592653589793" upper="3.141592653589793"/>
    </joint>
    <!-- Link roller_43 -->
    <link name="roller_43">
        <inertial>
            <origin xyz="1.70918e-16 -1.32732e-16 -4.21148e-16" rpy="0 0 0"/>
            <mass value="0.0493467"/>
            <inertia ixx="1.86522e-05" ixy="-2.10534e-21" ixz="1.36336e-21" iyy="1.86522e-05" iyz="-8.03849e-22" izz="5.80503e-06"/>
        </inertial>
        <!-- Part roller_43_parts -->
        <collision>
            <origin xyz="-2.86275e-18 6.9147e-18 -1.87858e-16" rpy="-1.19398e-16 -7.37282e-17 -3.68637e-17"/>
            <geometry>
                <sphere radius="0.0155"/>
            </geometry>
        </collision>
        <collision>
            <origin xyz="-6.55942e-18 -5.68803e-18 0.0085" rpy="-1.19398e-16 -7.37282e-17 -3.68637e-17"/>
            <geometry>
                <sphere radius="0.0155"/>
            </geometry>
        </collision>
        <collision>
            <origin xyz="1.01534e-18 1.91212e-17 -0.0085" rpy="-1.19398e-16 -7.37282e-17 -3.68637e-17"/>
            <geometry>
                <sphere radius="0.0155"/>
            </geometry>
        </collision>
        <collision>
            <origin xyz="-5.72154e-18 -4.07729e-18 0.0165" rpy="-1.19398e-16 -7.37282e-17 -3.68637e-17"/>
            <geometry>
                <sphere radius="0.015"/>
            </geometry>
        </collision>
        <collision>
            <origin xyz="-1.14412e-18 1.92351e-17 -0.0165" rpy="-1.19398e-16 -7.37282e-17 -3.68637e-17"/>
            <geometry>
                <sphere radius="0.015"/>
            </geometry>
        </collision>
        <collision>
            <origin xyz="7.68106e-18 2.29925e-17 0.0235" rpy="-1.19398e-16 -7.37282e-17 -3.68637e-17"/>
            <geometry>
                <sphere radius="0.014"/>
            </geometry>
        </collision>
        <collision>
            <origin xyz="-1.30083e-17 -9.12556e-18 -0.0235" rpy="-1.19398e-16 -7.37282e-17 -3.68637e-17"/>
            <geometry>
                <sphere radius="0.014"/>
            </geometry>
        </collision>
        <visual>
            <origin xyz="1.66533e-16 -1.38778e-16 -4.16334e-16" rpy="-0.914517 -0.467917 0.145054"/>
            <geometry>
                <mesh filename="package://assets/merged/roller_43_visual.stl"/>
            </geometry>
            <material name="roller_43_parts_material">
                <color rgba="0.752941 0.752941 0.752941 1.0"/>
            </material>
        </visual>
    </link>
    <!-- Joint from back_right_wheel to roller_43 -->
    <joint name="brw_r7" type="revolute">
        <origin xyz="-0.0662338 -0.0548551 -0.039" rpy="2.39411 -0.268603 -2.72874"/>
        <parent link="back_right_wheel"/>
        <child link="roller_43"/>
        <axis xyz="0 0 1"/>
        <limit effort="10" velocity="10" lower="-3.141592653589793" upper="3.141592653589793"/>
    </joint>
    <!-- Link roller_44 -->
    <link name="roller_44">
        <inertial>
            <origin xyz="1.77151e-16 -1.07894e-16 -3.93758e-16" rpy="0 0 0"/>
            <mass value="0.0493467"/>
            <inertia ixx="1.86522e-05" ixy="3.96417e-22" ixz="-9.9519e-23" iyy="1.86522e-05" iyz="-2.76231e-21" izz="5.80503e-06"/>
        </inertial>
        <!-- Part roller_44_parts -->
        <collision>
            <origin xyz="3.37087e-18 3.17523e-17 -1.60468e-16" rpy="-1.13532e-16 -7.72455e-17 -2.85346e-17"/>
            <geometry>
                <sphere radius="0.0155"/>
            </geometry>
        </collision>
        <collision>
            <origin xyz="-1.50928e-18 4.82916e-17 0.0085" rpy="-1.13532e-16 -7.72455e-17 -2.85346e-17"/>
            <geometry>
                <sphere radius="0.0155"/>
            </geometry>
        </collision>
        <collision>
            <origin xyz="8.38199e-18 1.50472e-17 -0.0085" rpy="-1.13532e-16 -7.72455e-17 -2.85346e-17"/>
            <geometry>
                <sphere radius="0.0155"/>
            </geometry>
        </collision>
        <collision>
            <origin xyz="-4.69789e-18 3.40504e-17 0.0165" rpy="-1.13532e-16 -7.72455e-17 -2.85346e-17"/>
            <geometry>
                <sphere radius="0.015"/>
            </geometry>
        </collision>
        <collision>
            <origin xyz="1.13538e-17 2.92884e-17 -0.0165" rpy="-1.13532e-16 -7.72455e-17 -2.85346e-17"/>
            <geometry>
                <sphere radius="0.015"/>
            </geometry>
        </collision>
        <collision>
            <origin xyz="4.67413e-19 5.03206e-17 0.0235" rpy="-1.13532e-16 -7.72455e-17 -2.85346e-17"/>
            <geometry>
                <sphere radius="0.014"/>
            </geometry>
        </collision>
        <collision>
            <origin xyz="5.44904e-18 8.09859e-18 -0.0235" rpy="-1.13532e-16 -7.72455e-17 -2.85346e-17"/>
            <geometry>
                <sphere radius="0.014"/>
            </geometry>
        </collision>
        <visual>
            <origin xyz="1.66533e-16 -1.11022e-16 -3.88578e-16" rpy="-0.792496 -0.118587 -0.265302"/>
            <geometry>
                <mesh filename="package://assets/merged/roller_44_visual.stl"/>
            </geometry>
            <material name="roller_44_parts_material">
                <color rgba="0.752941 0.752941 0.752941 1.0"/>
            </material>
        </visual>
    </link>
    <!-- Joint from back_right_wheel to roller_44 -->
    <joint name="brw_r8" type="revolute">
        <origin xyz="-0.0847877 -0.014389 -0.039" rpy="2.39411 -0.268603 3.03084"/>
        <parent link="back_right_wheel"/>
        <child link="roller_44"/>
        <axis xyz="0 0 1"/>
        <limit effort="10" velocity="10" lower="-3.141592653589793" upper="3.141592653589793"/>
    </joint>
    <!-- Link roller_45 -->
    <link name="roller_45">
        <inertial>
            <origin xyz="2.14256e-16 -1.15688e-16 -4.56969e-16" rpy="0 0 0"/>
            <mass value="0.0493467"/>
            <inertia ixx="1.86522e-05" ixy="-4.45181e-21" ixz="3.00632e-21" iyy="1.86522e-05" iyz="-1.70193e-21" izz="5.80503e-06"/>
        </inertial>
        <!-- Part roller_45_parts -->
        <collision>
            <origin xyz="4.04761e-17 2.39588e-17 -2.23679e-16" rpy="-1.71015e-16 -3.61072e-17 -4.91892e-17"/>
            <geometry>
                <sphere radius="0.0155"/>
            </geometry>
        </collision>
        <collision>
            <origin xyz="4.27428e-17 6.18553e-18 0.0085" rpy="-1.71015e-16 -3.61072e-17 -4.91892e-17"/>
            <geometry>
                <sphere radius="0.0155"/>
            </geometry>
        </collision>
        <collision>
            <origin xyz="3.81637e-17 4.18273e-17 -0.0085" rpy="-1.71015e-16 -3.61072e-17 -4.91892e-17"/>
            <geometry>
                <sphere radius="0.0155"/>
            </geometry>
        </collision>
        <collision>
            <origin xyz="3.10782e-17 1.66961e-17 0.0165" rpy="-1.71015e-16 -3.61072e-17 -4.91892e-17"/>
            <geometry>
                <sphere radius="0.015"/>
            </geometry>
        </collision>
        <collision>
            <origin xyz="4.98283e-17 3.0883e-17 -0.0165" rpy="-1.71015e-16 -3.61072e-17 -4.91892e-17"/>
            <geometry>
                <sphere radius="0.015"/>
            </geometry>
        </collision>
        <collision>
            <origin xyz="3.6608e-17 5.22109e-17 0.0235" rpy="-1.71015e-16 -3.61072e-17 -4.91892e-17"/>
            <geometry>
                <sphere radius="0.014"/>
            </geometry>
        </collision>
        <collision>
            <origin xyz="4.51658e-17 -3.76445e-18 -0.0235" rpy="-1.71015e-16 -3.61072e-17 -4.91892e-17"/>
            <geometry>
                <sphere radius="0.014"/>
            </geometry>
        </collision>
        <visual>
            <origin xyz="2.22045e-16 -1.17961e-16 -4.44089e-16" rpy="-0.817659 0.248666 -0.641464"/>
            <geometry>
                <mesh filename="package://assets/merged/roller_45_visual.stl"/>
            </geometry>
            <material name="roller_45_parts_material">
                <color rgba="0.752941 0.752941 0.752941 1.0"/>
            </material>
        </visual>
    </link>
    <!-- Joint from back_right_wheel to roller_45 -->
    <joint name="brw_r9" type="revolute">
        <origin xyz="-0.0806228 0.0299326 -0.039" rpy="2.39411 -0.268603 2.50724"/>
        <parent link="back_right_wheel"/>
        <child link="roller_45"/>
        <axis xyz="0 0 1"/>
        <limit effort="10" velocity="10" lower="-3.141592653589793" upper="3.141592653589793"/>
    </joint>
    <!-- Link roller_46 -->
    <link name="roller_46">
        <inertial>
            <origin xyz="1.59958e-16 -5.19151e-17 -3.13194e-16" rpy="0 0 0"/>
            <mass value="0.0493467"/>
            <inertia ixx="1.86522e-05" ixy="5.70983e-22" ixz="1.44447e-21" iyy="1.86522e-05" iyz="-3.29354e-21" izz="5.80503e-06"/>
        </inertial>
        <!-- Part roller_46_parts -->
        <collision>
            <origin xyz="-1.38226e-17 8.77316e-17 -7.99036e-17" rpy="-2.54752e-16 -1.29906e-16 1.24055e-16"/>
            <geometry>
                <sphere radius="0.0155"/>
            </geometry>
        </collision>
        <collision>
            <origin xyz="-2.02157e-17 8.72205e-17 0.0085" rpy="-2.54752e-16 -1.29906e-16 1.24055e-16"/>
            <geometry>
                <sphere radius="0.0155"/>
            </geometry>
        </collision>
        <collision>
            <origin xyz="-7.744e-18 8.80717e-17 -0.0085" rpy="-2.54752e-16 -1.29906e-16 1.24055e-16"/>
            <geometry>
                <sphere radius="0.0155"/>
            </geometry>
        </collision>
        <collision>
            <origin xyz="-2.8849e-17 1.05925e-16 0.0165" rpy="-2.54752e-16 -1.29906e-16 1.24055e-16"/>
            <geometry>
                <sphere radius="0.015"/>
            </geometry>
        </collision>
        <collision>
            <origin xyz="8.89217e-19 6.89338e-17 -0.0165" rpy="-2.54752e-16 -1.29906e-16 1.24055e-16"/>
            <geometry>
                <sphere radius="0.015"/>
            </geometry>
        </collision>
        <collision>
            <origin xyz="-3.44706e-17 9.82704e-17 0.0235" rpy="-2.54752e-16 -1.29906e-16 1.24055e-16"/>
            <geometry>
                <sphere radius="0.014"/>
            </geometry>
        </collision>
        <collision>
            <origin xyz="7.37822e-18 7.74555e-17 -0.0235" rpy="-2.54752e-16 -1.29906e-16 1.24055e-16"/>
            <geometry>
                <sphere radius="0.014"/>
            </geometry>
        </collision>
        <visual>
            <origin xyz="1.52656e-16 -2.77556e-17 -2.77556e-16" rpy="-1.90574 0.724678 -0.868219"/>
            <geometry>
                <mesh filename="package://assets/merged/roller_46_visual.stl"/>
            </geometry>
            <material name="roller_46_parts_material">
                <color rgba="0.752941 0.752941 0.752941 1.0"/>
            </material>
        </visual>
    </link>
    <!-- Joint from back_right_wheel to roller_46 -->
    <joint name="brw_r10" type="revolute">
        <origin xyz="0.0299326 0.0806228 -0.039" rpy="2.78255 0.714734 2.26605"/>
        <parent link="back_right_wheel"/>
        <child link="roller_46"/>
        <axis xyz="0 0 1"/>
        <limit effort="10" velocity="10" lower="-3.141592653589793" upper="3.141592653589793"/>
    </joint>
    <!-- Link roller_47 -->
    <link name="roller_47">
        <inertial>
            <origin xyz="1.51623e-16 -1.42463e-16 -4.15238e-16" rpy="0 0 0"/>
            <mass value="0.0493467"/>
            <inertia ixx="1.86522e-05" ixy="1.38098e-21" ixz="4.78471e-21" iyy="1.86522e-05" iyz="-2.57497e-21" izz="5.80503e-06"/>
        </inertial>
        <!-- Part roller_47_parts -->
        <collision>
            <origin xyz="-2.21569e-17 -2.81594e-18 -1.81948e-16" rpy="-2.44428e-16 -2.24265e-16 2.12555e-17"/>
            <geometry>
                <sphere radius="0.0155"/>
            </geometry>
        </collision>
        <collision>
            <origin xyz="-3.28692e-17 8.45485e-18 0.0085" rpy="-2.44428e-16 -2.24265e-16 2.12555e-17"/>
            <geometry>
                <sphere radius="0.0155"/>
            </geometry>
        </collision>
        <collision>
            <origin xyz="-1.16681e-17 -1.40421e-17 -0.0085" rpy="-2.44428e-16 -2.24265e-16 2.12555e-17"/>
            <geometry>
                <sphere radius="0.0155"/>
            </geometry>
        </collision>
        <collision>
            <origin xyz="-4.57979e-17 1.83808e-17 0.0165" rpy="-2.44428e-16 -2.24265e-16 2.12555e-17"/>
            <geometry>
                <sphere radius="0.015"/>
            </geometry>
        </collision>
        <collision>
            <origin xyz="1.26055e-18 -2.41848e-17 -0.0165" rpy="-2.44428e-16 -2.24265e-16 2.12555e-17"/>
            <geometry>
                <sphere radius="0.015"/>
            </geometry>
        </collision>
        <collision>
            <origin xyz="-2.53813e-17 1.08081e-17 0.0235" rpy="-2.44428e-16 -2.24265e-16 2.12555e-17"/>
            <geometry>
                <sphere radius="0.014"/>
            </geometry>
        </collision>
        <collision>
            <origin xyz="-1.9156e-17 -1.66122e-17 -0.0235" rpy="-2.44428e-16 -2.24265e-16 2.12555e-17"/>
            <geometry>
                <sphere radius="0.014"/>
            </geometry>
        </collision>
        <visual>
            <origin xyz="1.45717e-16 -1.38778e-16 -3.88578e-16" rpy="-1.40502 0.771399 -0.149186"/>
            <geometry>
                <mesh filename="package://assets/merged/roller_47_visual.stl"/>
            </geometry>
            <material name="roller_47_parts_material">
                <color rgba="0.752941 0.752941 0.752941 1.0"/>
            </material>
        </visual>
    </link>
    <!-- Joint from back_right_wheel to roller_47 -->
    <joint name="brw_r11" type="revolute">
        <origin xyz="-0.014389 0.0847877 -0.039" rpy="2.78255 0.714734 2.78965"/>
        <parent link="back_right_wheel"/>
        <child link="roller_47"/>
        <axis xyz="0 0 1"/>
        <limit effort="10" velocity="10" lower="-3.141592653589793" upper="3.141592653589793"/>
    </joint>
    <!-- Link roller_48 -->
    <link name="roller_48">
        <inertial>
            <origin xyz="2.9144e-16 -1.67669e-16 -3.47883e-16" rpy="0 0 0"/>
            <mass value="0.0493467"/>
            <inertia ixx="1.86522e-05" ixy="6.19404e-22" ixz="-3.23116e-22" iyy="1.86522e-05" iyz="-5.83345e-21" izz="5.80503e-06"/>
        </inertial>
        <!-- Part roller_48_parts -->
        <collision>
            <origin xyz="1.17659e-16 -2.80223e-17 -1.14593e-16" rpy="-3.10488e-16 -2.61986e-17 2.86791e-17"/>
            <geometry>
                <sphere radius="0.0155"/>
            </geometry>
        </collision>
        <collision>
            <origin xyz="1.18537e-16 -2.0616e-17 0.0085" rpy="-3.10488e-16 -2.61986e-17 2.86791e-17"/>
            <geometry>
                <sphere radius="0.0155"/>
            </geometry>
        </collision>
        <collision>
            <origin xyz="1.17118e-16 -3.51669e-17 -0.0085" rpy="-3.10488e-16 -2.61986e-17 2.86791e-17"/>
            <geometry>
                <sphere radius="0.0155"/>
            </geometry>
        </collision>
        <collision>
            <origin xyz="1.13008e-16 -2.93119e-17 0.0165" rpy="-3.10488e-16 -2.61986e-17 2.86791e-17"/>
            <geometry>
                <sphere radius="0.015"/>
            </geometry>
        </collision>
        <collision>
            <origin xyz="1.24437e-16 -3.95943e-17 -0.0165" rpy="-3.10488e-16 -2.61986e-17 2.86791e-17"/>
            <geometry>
                <sphere radius="0.015"/>
            </geometry>
        </collision>
        <collision>
            <origin xyz="1.19497e-16 -1.02925e-17 0.0235" rpy="-3.10488e-16 -2.61986e-17 2.86791e-17"/>
            <geometry>
                <sphere radius="0.014"/>
            </geometry>
        </collision>
        <collision>
            <origin xyz="1.15291e-16 -4.63578e-17 -0.0235" rpy="-3.10488e-16 -2.61986e-17 2.86791e-17"/>
            <geometry>
                <sphere radius="0.014"/>
            </geometry>
        </collision>
        <visual>
            <origin xyz="2.94469e-16 -1.73472e-16 -3.33067e-16" rpy="-1.00301 0.575895 0.479378"/>
            <geometry>
                <mesh filename="package://assets/merged/roller_48_visual.stl"/>
            </geometry>
            <material name="roller_48_parts_material">
                <color rgba="0.752941 0.752941 0.752941 1.0"/>
            </material>
        </visual>
    </link>
    <!-- Joint from back_right_wheel to roller_48 -->
    <joint name="brw_r12" type="revolute">
        <origin xyz="-0.0548551 0.0662338 -0.039" rpy="2.78255 0.714734 -2.96994"/>
        <parent link="back_right_wheel"/>
        <child link="roller_48"/>
        <axis xyz="0 0 1"/>
        <limit effort="10" velocity="10" lower="-3.141592653589793" upper="3.141592653589793"/>
    </joint>
    <!-- Joint from base_link to back_right_wheel -->
    <joint name="back_right_wheel" type="continuous">
        <origin xyz="-0.2735 -0.24 0.065" rpy="1.5708 4.89325e-15 -3.14159"/>
        <parent link="base_link"/>
        <child link="back_right_wheel"/>
        <axis xyz="0 0 1"/>
        <limit effort="10" velocity="10"/>
    </joint>
</robot>
